Workbook

Sheet TAX
A2: ຕາຕະລາງຄິດໄລ່ອາກອນເງິນເດືອນ
A3: ບໍລິສັດ ມິຢາໂມໂຕ້ (ລາວ) ຈຳກັດຜູ້ດຽວ
A4: ບ້ານໜອງຜື ນຄອນໄກສອນ ແຂວງສະຫວັນນະເຂດ
A5: ໂທ: 020 23333500 | F5: ຕ່າງປະເທດ
A6: No | B6: Employee ID | C6: Employee Name | D6: Phone Number | E6: Position | F6: Nationality | G6: Working Days | H6: Basic Salary | I6: Overtime Pay | J6: Night Shift Allowance | K6: Safety Allowance | L6: Cooperation Allowance | M6: Other Allowance | N6: Diligence Allowance | O6: 5S Allowance | P6: Housing Allowance | Q6: Production Target Allowance | R6: Position Allowance | S6: Fuel Allowance | T6: Total Earnings | U6: Social Security | V6: Late Penalty (1-10 mins) | W6: Late Penalty (10-30 mins) | X6: Late Penalty (30+ mins) | Y6: Absence Deduction | Z6: incomplete Month Deduction | AA6: Total Deductions | AB6: Taxable Income | AC6: Tax Exemption (200,000 LAK) | AD6: Income Tax (5%) | AE6: Net Income | AF6: Salary Advance Deduction | AG6: Net Salary Paid | AH6: Column1 | AI6: Column2 | AJ6: Column3 | AK6: Bank Account | AL6: Salary | AM6: Deduction | AN6: Before Tax | AO6: Other Benefits | AP6: Column4
A7: {=_xlfn.SEQUENCE(COUNTA(B7:B136))} -> 1 | B7: MYL000001 | C7: MR PHICHAI EIAMWATTANASILP | D7: 66617893562 | E7: Director | F7: ຕ່າງປະເທດ | G7: 26 | H7: =100000*680.67 -> 68067000 | I7: =SUMIF($B$7:$B$175,OT!B8,OT!$S$8:$S$160) -> 0 | J7: =SUMIF($B$7:$B$136,เงินกะ!B8,เงินกะ!$M$8:$M$100) -> 0 | T7: =SUM(H7:S7) -> 68067000 | V7: =SUMIF($B$7:$B$136,'ขาด-ลา-มาสาย'!B8,'ขาด-ลา-มาสาย'!$K$8:$K$100) -> 0 | W7: =SUMIF($B$7:$B$136,'ขาด-ลา-มาสาย'!B8,'ขาด-ลา-มาสาย'!$N$8:$N$100) -> 0 | X7: =SUMIF($B$7:$B$136,'ขาด-ลา-มาสาย'!B8,'ขาด-ลา-มาสาย'!$Q$8:$Q$100) -> 0 | Y7: =SUMIF($B$7:$B$136,'ขาด-ลา-มาสาย'!B8,'ขาด-ลา-มาสาย'!$T$8:$T$100) -> 0 | Z7: =SUMIF($B$7:$B$136,'ขาด-ลา-มาสาย'!B8,'ขาด-ลา-มาสาย'!$W$8:$W$100) -> 0 | AA7: =SUM(U7:Z7) -> 0 | AB7: =T7-AA7 -> 68067000 | AC7: =AB7-0 -> 68067000 | AD7: =AC7*5% -> 3403350 | AE7: =AB7-AD7 -> 64663650 | AG7: =AE7-AF7 -> 64663650 | AH7: OF | AI7: =AE7/680 -> 95093.603 | AK7: NO ACCOUNT | AL7: =H7 -> 68067000 | AM7: =AA7 -> 0 | AN7: =AL7-AM7 -> 68067000 | AO7: =SUM(I7:S7) -> 0 | AP7: =AE7 -> 64663650 | AQ7: 68081000
A8: 2 | B8: MYL000005 | C8: MR WEERASIT LEEGCHOUR | D8: 2098388245 | E8: Deputy director 04 | F8: ຕ່າງປະເທດ | G8: 26 | H8: =20000*680.67 -> 13613400 | I8: =SUMIF($B$7:$B$175,OT!B9,OT!$S$8:$S$160) -> 0 | J8: =SUMIF($B$7:$B$136,เงินกะ!B9,เงินกะ!$M$8:$M$100) -> 0 | T8: =SUM(H8:S8) -> 13613400 | V8: =SUMIF($B$7:$B$136,'ขาด-ลา-มาสาย'!B9,'ขาด-ลา-มาสาย'!$K$8:$K$100) -> 0 | W8: =SUMIF($B$7:$B$136,'ขาด-ลา-มาสาย'!B9,'ขาด-ลา-มาสาย'!$N$8:$N$100) -> 0 | X8: =SUMIF($B$7:$B$136,'ขาด-ลา-มาสาย'!B9,'ขาด-ลา-มาสาย'!$Q$8:$Q$100) -> 0 | Y8: =SUMIF($B$7:$B$136,'ขาด-ลา-มาสาย'!B9,'ขาด-ลา-มาสาย'!$T$8:$T$100) -> 0 | Z8: =SUMIF($B$7:$B$136,'ขาด-ลา-มาสาย'!B9,'ขาด-ลา-มาสาย'!$W$8:$W$100) -> 0 | AA8: =SUM(U8:Z8) -> 0 | AB8: =T8-AA8 -> 13613400 | AC8: =AB8-0 -> 13613400 | AD8: =AC8*5% -> 680670 | AE8: =AB8-AD8 -> 12932730 | AG8: =AE8-AF8 -> 12932730 | AH8: OF | AI8: =AE8/680 -> 19018.721 | AK8: NO ACCOUNT | AL8: =H8 -> 13613400 | AM8: =AA8 -> 0 | AN8: =AL8-AM8 -> 13613400 | AO8: =SUM(I8:S8) -> 0 | AP8: =AE8 -> 12932730
A9: 3 | B9: MYL000002 | C9: MRS Boualavanh BANPHACHA | D9: 2023333500 | E9: Deputy director 01 | F9: ພາຍໃນປະເທດ | G9: 26 | H9: =100000*680.67 -> 68067000 | I9: =SUMIF($B$7:$B$175,OT!B10,OT!$S$8:$S$160) -> 0 | J9: =SUMIF($B$7:$B$136,เงินกะ!B10,เงินกะ!$M$8:$M$100) -> 0 | T9: =SUM(H9:S9) -> 68067000 | V9: =SUMIF($B$7:$B$136,'ขาด-ลา-มาสาย'!B10,'ขาด-ลา-มาสาย'!$K$8:$K$100) -> 0 | W9: =SUMIF($B$7:$B$136,'ขาด-ลา-มาสาย'!B10,'ขาด-ลา-มาสาย'!$N$8:$N$100) -> 0 | X9: =SUMIF($B$7:$B$136,'ขาด-ลา-มาสาย'!B10,'ขาด-ลา-มาสาย'!$Q$8:$Q$100) -> 0 | Y9: =SUMIF($B$7:$B$136,'ขาด-ลา-มาสาย'!B10,'ขาด-ลา-มาสาย'!$T$8:$T$100) -> 0 | Z9: =SUMIF($B$7:$B$136,'ขาด-ลา-มาสาย'!B10,'ขาด-ลา-มาสาย'!$W$8:$W$100) -> 0 | AA9: =SUM(U9:Z9) -> 0 | AB9: =T9-AA9 -> 68067000 | AC9: =AB9-200000 -> 67867000 | AD9: =AC9*5% -> 3393350 | AE9: =AB9-AD9 -> 64673650 | AG9: =AE9-AF9 -> 64673650 | AH9: OF | AI9: =AE9/680 -> 95108.309 | AK9: NO ACCOUNT | AL9: =H9 -> 68067000 | AM9: =AA9 -> 0 | AN9: =AL9-AM9 -> 68067000 | AO9: =SUM(I9:S9) -> 0 | AP9: =AE9 -> 64673650
A10: 4 | B10: MYL000003 | C10: MRS DATSANY BANPHAXA | D10: 2023333800 | E10: Deputy director 02 | F10: ພາຍໃນປະເທດ | G10: 26 | H10: =40000*680.67 -> 27226800 | I10: =SUMIF($B$7:$B$175,OT!B11,OT!$S$8:$S$160) -> 0 | J10: =SUMIF($B$7:$B$136,เงินกะ!B11,เงินกะ!$M$8:$M$100) -> 0 | R10: =18000*680.81 -> 12254580 | T10: =SUM(H10:S10) -> 39481380 | V10: =SUMIF($B$7:$B$136,'ขาด-ลา-มาสาย'!B11,'ขาด-ลา-มาสาย'!$K$8:$K$100) -> 0 | W10: =SUMIF($B$7:$B$136,'ขาด-ลา-มาสาย'!B11,'ขาด-ลา-มาสาย'!$N$8:$N$100) -> 0 | X10: =SUMIF($B$7:$B$136,'ขาด-ลา-มาสาย'!B11,'ขาด-ลา-มาสาย'!$Q$8:$Q$100) -> 0 | Y10: =SUMIF($B$7:$B$136,'ขาด-ลา-มาสาย'!B11,'ขาด-ลา-มาสาย'!$T$8:$T$100) -> 0 | Z10: =SUMIF($B$7:$B$136,'ขาด-ลา-มาสาย'!B11,'ขาด-ลา-มาสาย'!$W$8:$W$100) -> 0 | AA10: =SUM(U10:Z10) -> 0 | AB10: =T10-AA10 -> 39481380 | AC10: =AB10-200000 -> 39281380 | AD10: =AC10*5% -> 1964069 | AE10: =AB10-AD10 -> 37517311 | AG10: =AE10-AF10 -> 37517311 | AH10: OF | AI10: =AE10/680 -> 55172.516 | AK10: NO ACCOUNT | AL10: =H10 -> 27226800 | AM10: =AA10 -> 0 | AN10: =AL10-AM10 -> 27226800 | AO10: =SUM(I10:S10) -> 12254580 | AP10: =AE10 -> 37517311
A11: 5 | B11: MYL000004 | C11: MISS BOUAVONE VANGVONGXAI | D11: 2076198111 | E11: Deputy director 03 | F11: ພາຍໃນປະເທດ | G11: 26 | H11: 13000000 | I11: =SUMIF($B$7:$B$175,OT!B12,OT!$S$8:$S$160) -> 0 | J11: =SUMIF($B$7:$B$136,เงินกะ!B12,เงินกะ!$M$8:$M$100) -> 0 | T11: =SUM(H11:S11) -> 13000000 | V11: =SUMIF($B$7:$B$136,'ขาด-ลา-มาสาย'!B12,'ขาด-ลา-มาสาย'!$K$8:$K$100) -> 0 | W11: =SUMIF($B$7:$B$136,'ขาด-ลา-มาสาย'!B12,'ขาด-ลา-มาสาย'!$N$8:$N$100) -> 0 | X11: =SUMIF($B$7:$B$136,'ขาด-ลา-มาสาย'!B12,'ขาด-ลา-มาสาย'!$Q$8:$Q$100) -> 0 | Y11: =SUMIF($B$7:$B$136,'ขาด-ลา-มาสาย'!B12,'ขาด-ลา-มาสาย'!$T$8:$T$100) -> 0 | Z11: =SUMIF($B$7:$B$136,'ขาด-ลา-มาสาย'!B12,'ขาด-ลา-มาสาย'!$W$8:$W$100) -> 0 | AA11: =SUM(U11:Z11) -> 0 | AB11: =T11-AA11 -> 13000000 | AC11: =AB11-200000 -> 12800000 | AD11: =AC11*5% -> 640000 | AE11: =AB11-AD11 -> 12360000 | AG11: =AE11-AF11 -> 12360000 | AH11: OF | AI11: =AE11/680 -> 18176.471 | AK11: 020-4-00-00-14636 | AL11: =H11 -> 13000000 | AM11: =AA11 -> 0 | AN11: =AL11-AM11 -> 13000000 | AO11: =SUM(I11:S11) -> 0 | AP11: =AE11 -> 12360000
A12: 6 | B12: MYL202210001 | C12: MR ANOUSACK THAMMAVONG | D12: 2077772708 | E12: Accounting | F12: ພາຍໃນປະເທດ | G12: 26 | H12: 10000000 | I12: =SUMIF($B$7:$B$175,OT!B13,OT!$S$8:$S$160) -> 0 | J12: =SUMIF($B$7:$B$136,เงินกะ!B13,เงินกะ!$M$8:$M$100) -> 0 | T12: =SUM(H12:S12) -> 10000000 | V12: =SUMIF($B$7:$B$136,'ขาด-ลา-มาสาย'!B13,'ขาด-ลา-มาสาย'!$K$8:$K$100) -> 0 | W12: =SUMIF($B$7:$B$136,'ขาด-ลา-มาสาย'!B13,'ขาด-ลา-มาสาย'!$N$8:$N$100) -> 0 | X12: =SUMIF($B$7:$B$136,'ขาด-ลา-มาสาย'!B13,'ขาด-ลา-มาสาย'!$Q$8:$Q$100) -> 0 | Y12: =SUMIF($B$7:$B$136,'ขาด-ลา-มาสาย'!B13,'ขาด-ลา-มาสาย'!$T$8:$T$100) -> 0 | Z12: =SUMIF($B$7:$B$136,'ขาด-ลา-มาสาย'!B13,'ขาด-ลา-มาสาย'!$W$8:$W$100) -> 0 | AA12: =SUM(U12:Z12) -> 0 | AB12: =T12-AA12 -> 10000000 | AC12: =AB12-200000 -> 9800000 | AD12: =AC12*5% -> 490000 | AE12: =AB12-AD12 -> 9510000 | AG12: =AE12-AF12 -> 9510000 | AH12: OF | AI12: =AE12/680 -> 13985.294 | AK12: 034-5-02-00-00385 | AL12: =H12 -> 10000000 | AM12: =AA12 -> 0 | AN12: =AL12-AM12 -> 10000000 | AO12: =SUM(I12:S12) -> 0 | AP12: =AE12 -> 9510000
A13: 7 | B13: MYL202001001 | C13: MR SONESAVANH PHENGPHINIT | D13: 02092539860 | E13: Accounting | F13: ພາຍໃນປະເທດ | G13: 26 | H13: 6832000 | I13: =SUMIF($B$7:$B$175,OT!B14,OT!$S$8:$S$160) -> 0 | J13: =SUMIF($B$7:$B$136,เงินกะ!B14,เงินกะ!$M$8:$M$100) -> 0 | T13: =SUM(H13:S13) -> 6832000 | V13: =SUMIF($B$7:$B$136,'ขาด-ลา-มาสาย'!B14,'ขาด-ลา-มาสาย'!$K$8:$K$100) -> 0 | W13: =SUMIF($B$7:$B$136,'ขาด-ลา-มาสาย'!B14,'ขาด-ลา-มาสาย'!$N$8:$N$100) -> 0 | X13: =SUMIF($B$7:$B$136,'ขาด-ลา-มาสาย'!B14,'ขาด-ลา-มาสาย'!$Q$8:$Q$100) -> 0 | Y13: =SUMIF($B$7:$B$136,'ขาด-ลา-มาสาย'!B14,'ขาด-ลา-มาสาย'!$T$8:$T$100) -> 0 | Z13: =SUMIF($B$7:$B$136,'ขาด-ลา-มาสาย'!B14,'ขาด-ลา-มาสาย'!$W$8:$W$100) -> 0 | AA13: =SUM(U13:Z13) -> 0 | AB13: =T13-AA13 -> 6832000 | AC13: =AB13-200000 -> 6632000 | AD13: =AC13*5% -> 331600 | AE13: =AB13-AD13 -> 6500400 | AG13: =AE13-AF13 -> 6500400 | AH13: OF | AI13: =AE13/680 -> 9559.4118 | AK13: 030-7-00-00-05957 | AL13: =H13 -> 6832000 | AM13: =AA13 -> 0 | AN13: =AL13-AM13 -> 6832000 | AO13: =SUM(I13:S13) -> 0 | AP13: =AE13 -> 6500400
A14: 8 | B14: MYL202408005 | C14: MISS CHANSAMONE PHANTHALAVONG | D14: 2099701293 | E14: Planning | F14: ພາຍໃນປະເທດ | G14: 26 | H14: 6000000 | I14: =SUMIF($B$7:$B$175,OT!B15,OT!$S$8:$S$160) -> 0 | J14: =SUMIF($B$7:$B$136,เงินกะ!B15,เงินกะ!$M$8:$M$100) -> 0 | R14: 2000000 | T14: =SUM(H14:S14) -> 8000000 | V14: =SUMIF($B$7:$B$136,'ขาด-ลา-มาสาย'!B15,'ขาด-ลา-มาสาย'!$K$8:$K$100) -> 0 | W14: =SUMIF($B$7:$B$136,'ขาด-ลา-มาสาย'!B15,'ขาด-ลา-มาสาย'!$N$8:$N$100) -> 0 | X14: =SUMIF($B$7:$B$136,'ขาด-ลา-มาสาย'!B15,'ขาด-ลา-มาสาย'!$Q$8:$Q$100) -> 0 | Y14: =SUMIF($B$7:$B$136,'ขาด-ลา-มาสาย'!B15,'ขาด-ลา-มาสาย'!$T$8:$T$100) -> 0 | Z14: =SUMIF($B$7:$B$136,'ขาด-ลา-มาสาย'!B15,'ขาด-ลา-มาสาย'!$W$8:$W$100) -> 0 | AA14: =SUM(U14:Z14) -> 0 | AB14: =T14-AA14 -> 8000000 | AC14: =AB14-200000 -> 7800000 | AD14: =AC14*5% -> 390000 | AE14: =AB14-AD14 -> 7610000 | AG14: =AE14-AF14 -> 7610000 | AH14: OF | AI14: =AE14/680 -> 11191.176 | AK14: 190-9-00-00-00951 | AL14: =H14 -> 6000000 | AM14: =AA14 -> 0 | AN14: =AL14-AM14 -> 6000000 | AO14: =SUM(I14:S14) -> 2000000 | AP14: =AE14 -> 7610000
A15: 9 | B15: MYT202602136 | C15: MRS BOUANGUEN SOMCHANMAVONG | D15: 2056516668 | E15: Planning | F15: ພາຍໃນປະເທດ | G15: 26 | H15: 4500000 | I15: =SUMIF($B$7:$B$175,OT!B16,OT!$S$8:$S$160) -> 0 | J15: =SUMIF($B$7:$B$136,เงินกะ!B16,เงินกะ!$M$8:$M$100) -> 0 | R15: 1000000 | S15: =400000/26*25.5 -> 392307.69 | T15: =SUM(H15:S15) -> 5892307.7 | U15: 93500 | V15: =SUMIF($B$7:$B$136,'ขาด-ลา-มาสาย'!B16,'ขาด-ลา-มาสาย'!$K$8:$K$100) -> 0 | W15: =SUMIF($B$7:$B$136,'ขาด-ลา-มาสาย'!B16,'ขาด-ลา-มาสาย'!$N$8:$N$100) -> 0 | X15: =SUMIF($B$7:$B$136,'ขาด-ลา-มาสาย'!B16,'ขาด-ลา-มาสาย'!$Q$8:$Q$100) -> 0 | Y15: =SUMIF($B$7:$B$136,'ขาด-ลา-มาสาย'!B16,'ขาด-ลา-มาสาย'!$T$8:$T$100) -> 86538.462 | Z15: =SUMIF($B$7:$B$136,'ขาด-ลา-มาสาย'!B16,'ขาด-ลา-มาสาย'!$W$8:$W$100) -> 0 | AA15: =SUM(U15:Z15) -> 180038.46 | AB15: =T15-AA15 -> 5712269.2 | AC15: =AB15-200000 -> 5512269.2 | AD15: =AC15*5% -> 275613.46 | AE15: =AB15-AD15 -> 5436655.8 | AG15: =AE15-AF15 -> 5436655.8 | AH15: PD | AI15: =AE15/680 -> 7995.082 | AK15: 030-3-00-00-06998 | AL15: =H15 -> 4500000 | AM15: =AA15 -> 180038.46 | AN15: =AL15-AM15 -> 4319961.5 | AO15: =SUM(I15:S15) -> 1392307.7 | AP15: =AE15 -> 5436655.8
A16: 10 | B16: MYL202606153 | C16: MR SEUAPA XAIYAVONG | D16: 2078150776 | E16: Planning | F16: ພາຍໃນປະເທດ | G16: 26 | H16: 3500000 | I16: =SUMIF($B$7:$B$175,OT!B17,OT!$S$8:$S$160) -> 0 | J16: =SUMIF($B$7:$B$136,เงินกะ!B17,เงินกะ!$M$8:$M$100) -> 0 | R16: 1000000 | S16: =400000/26*23 -> 353846.15 | T16: =SUM(H16:S16) -> 4853846.2 | V16: =SUMIF($B$7:$B$136,'ขาด-ลา-มาสาย'!B17,'ขาด-ลา-มาสาย'!$K$8:$K$100) -> 0 | W16: =SUMIF($B$7:$B$136,'ขาด-ลา-มาสาย'!B17,'ขาด-ลา-มาสาย'!$N$8:$N$100) -> 0 | X16: =SUMIF($B$7:$B$136,'ขาด-ลา-มาสาย'!B17,'ขาด-ลา-มาสาย'!$Q$8:$Q$100) -> 0 | Y16: =SUMIF($B$7:$B$136,'ขาด-ลา-มาสาย'!B17,'ขาด-ลา-มาสาย'!$T$8:$T$100) -> 0 | Z16: =SUMIF($B$7:$B$136,'ขาด-ลา-มาสาย'!B17,'ขาด-ลา-มาสาย'!$W$8:$W$100) -> 403846.15 | AA16: =SUM(U16:Z16) -> 403846.15 | AB16: =T16-AA16 -> 4450000 | AC16: =AB16-200000 -> 4250000 | AD16: =AC16*5% -> 212500 | AE16: =AB16-AD16 -> 4237500 | AG16: =AE16-AF16 -> 4237500
A17: 11 | B17: MYL202604144 | C17: MISS PHOSEE KIANGLANOUSIN | D17: 2076861520 | E17: OFFICE | F17: ພາຍໃນປະເທດ | G17: 26 | H17: 3500000 | I17: =SUMIF($B$7:$B$175,OT!B18,OT!$S$8:$S$160) -> 0 | J17: =SUMIF($B$7:$B$136,เงินกะ!B18,เงินกะ!$M$8:$M$100) -> 0 | R17: 1000000 | S17: 400000 | T17: =SUM(H17:S17) -> 4900000 | V17: =SUMIF($B$7:$B$136,'ขาด-ลา-มาสาย'!B18,'ขาด-ลา-มาสาย'!$K$8:$K$100) -> 0 | W17: =SUMIF($B$7:$B$136,'ขาด-ลา-มาสาย'!B18,'ขาด-ลา-มาสาย'!$N$8:$N$100) -> 0 | X17: =SUMIF($B$7:$B$136,'ขาด-ลา-มาสาย'!B18,'ขาด-ลา-มาสาย'!$Q$8:$Q$100) -> 0 | Y17: =SUMIF($B$7:$B$136,'ขาด-ลา-มาสาย'!B18,'ขาด-ลา-มาสาย'!$T$8:$T$100) -> 0 | Z17: =SUMIF($B$7:$B$136,'ขาด-ลา-มาสาย'!B18,'ขาด-ลา-มาสาย'!$W$8:$W$100) -> 0 | AA17: =SUM(U17:Z17) -> 0 | AB17: =T17-AA17 -> 4900000 | AC17: =AB17-200000 -> 4700000 | AD17: =AC17*5% -> 235000 | AE17: =AB17-AD17 -> 4665000 | AG17: =AE17-AF17 -> 4665000 | AI17: =AE17/680 -> 6860.2941 | AK17: 030-4-00-00-07097 | AL17: =H17 -> 3500000 | AM17: =AA17 -> 0 | AN17: =AL17-AM17 -> 3500000 | AO17: =SUM(I17:S17) -> 1400000 | AP17: =AE17 -> 4665000
A18: 12 | B18: MYL201908010 | C18: MR SAYSAMPHAN MANEEBOTH | D18: 2097545680 | E18: Logistic Staff | F18: ພາຍໃນປະເທດ | G18: 26 | H18: 5000000 | I18: =SUMIF($B$7:$B$175,OT!B19,OT!$S$8:$S$160) -> 0 | J18: =SUMIF($B$7:$B$136,เงินกะ!B19,เงินกะ!$M$8:$M$100) -> 0 | R18: 5000000 | S18: =400000/26*24.5 -> 376923.08 | T18: =SUM(H18:S18) -> 10376923 | U18: 88000 | V18: =SUMIF($B$7:$B$136,'ขาด-ลา-มาสาย'!B19,'ขาด-ลา-มาสาย'!$K$8:$K$100) -> 0 | W18: =SUMIF($B$7:$B$136,'ขาด-ลา-มาสาย'!B19,'ขาด-ลา-มาสาย'!$N$8:$N$100) -> 0 | X18: =SUMIF($B$7:$B$136,'ขาด-ลา-มาสาย'!B19,'ขาด-ลา-มาสาย'!$Q$8:$Q$100) -> 0 | Y18: =SUMIF($B$7:$B$136,'ขาด-ลา-มาสาย'!B19,'ขาด-ลา-มาสาย'!$T$8:$T$100) -> 0 | Z18: =SUMIF($B$7:$B$136,'ขาด-ลา-มาสาย'!B19,'ขาด-ลา-มาสาย'!$W$8:$W$100) -> 0 | AA18: =SUM(U18:Z18) -> 88000 | AB18: =T18-AA18 -> 10288923 | AC18: =AB18-200000 -> 10088923 | AD18: =AC18*5% -> 504446.15 | AE18: =AB18-AD18 -> 9784476.9 | AG18: =AE18-AF18 -> 9784476.9 | AH18: PD | AI18: =AE18/680 -> 14388.937 | AK18: 034-0-02-00-00023 | AL18: =H18 -> 5000000 | AM18: =AA18 -> 88000 | AN18: =AL18-AM18 -> 4912000 | AO18: =SUM(I18:S18) -> 5376923.1 | AP18: =AE18 -> 9784476.9
A19: 13 | B19: MYL202001036 | C19: MISS JINDA BANPHACHA | D19: 2092416077 | E19: Audit | F19: ພາຍໃນປະເທດ | G19: 26 | H19: =15500*680.67 -> 10550385 | I19: =SUMIF($B$7:$B$175,OT!B20,OT!$S$8:$S$160) -> 0 | J19: =SUMIF($B$7:$B$136,เงินกะ!B20,เงินกะ!$M$8:$M$100) -> 0 | T19: =SUM(H19:S19) -> 10550385 | V19: =SUMIF($B$7:$B$136,'ขาด-ลา-มาสาย'!B20,'ขาด-ลา-มาสาย'!$K$8:$K$100) -> 0 | W19: =SUMIF($B$7:$B$136,'ขาด-ลา-มาสาย'!B20,'ขาด-ลา-มาสาย'!$N$8:$N$100) -> 0 | X19: =SUMIF($B$7:$B$136,'ขาด-ลา-มาสาย'!B20,'ขาด-ลา-มาสาย'!$Q$8:$Q$100) -> 0 | Y19: =SUMIF($B$7:$B$136,'ขาด-ลา-มาสาย'!B20,'ขาด-ลา-มาสาย'!$T$8:$T$100) -> 0 | Z19: =SUMIF($B$7:$B$136,'ขาด-ลา-มาสาย'!B20,'ขาด-ลา-มาสาย'!$W$8:$W$100) -> 0 | AA19: =SUM(U19:Z19) -> 0 | AB19: =T19-AA19 -> 10550385 | AC19: =AB19-200000 -> 10350385 | AD19: =AC19*5% -> 517519.25 | AE19: =AB19-AD19 -> 10032866 | AG19: =AE19-AF19 -> 10032866 | AH19: OF | AI19: =AE19/680 -> 14754.214 | AK19: NO ACCOUNT | AL19: =H19 -> 10550385 | AM19: =AA19 -> 0 | AN19: =AL19-AM19 -> 10550385 | AO19: =SUM(I19:S19) -> 0 | AP19: =AE19 -> 10032866
A20: 14 | B20: MYL201908016 | C20: MR AMMALIN | D20: 2023332299 | E20: Production manager 02 | F20: ພາຍໃນປະເທດ | G20: 26 | H20: 5000000 | I20: =SUMIF($B$7:$B$175,OT!B21,OT!$S$8:$S$160) -> 0 | J20: =SUMIF($B$7:$B$136,เงินกะ!B21,เงินกะ!$M$8:$M$100) -> 0 | R20: 5000000 | S20: 346153.85 | T20: =SUM(H20:S20) -> 10346154 | U20: 88000 | V20: =SUMIF($B$7:$B$136,'ขาด-ลา-มาสาย'!B21,'ขาด-ลา-มาสาย'!$K$8:$K$100) -> 0 | W20: =SUMIF($B$7:$B$136,'ขาด-ลา-มาสาย'!B21,'ขาด-ลา-มาสาย'!$N$8:$N$100) -> 0 | X20: =SUMIF($B$7:$B$136,'ขาด-ลา-มาสาย'!B21,'ขาด-ลา-มาสาย'!$Q$8:$Q$100) -> 0 | Y20: =SUMIF($B$7:$B$136,'ขาด-ลา-มาสาย'!B21,'ขาด-ลา-มาสาย'!$T$8:$T$100) -> 0 | Z20: =SUMIF($B$7:$B$136,'ขาด-ลา-มาสาย'!B21,'ขาด-ลา-มาสาย'!$W$8:$W$100) -> 0 | AA20: =SUM(U20:Z20) -> 88000 | AB20: =T20-AA20 -> 10258154 | AC20: =AB20-200000 -> 10058154 | AD20: =AC20*5% -> 502907.69 | AE20: =AB20-AD20 -> 9755246.2 | AG20: =AE20-AF20 -> 9755246.2 | AH20: PD | AI20: =AE20/680 -> 14345.95 | AK20: 034-6-02-00-00010 | AL20: =H20 -> 5000000 | AM20: =AA20 -> 88000 | AN20: =AL20-AM20 -> 4912000 | AO20: =SUM(I20:S20) -> 5346153.8 | AP20: =AE20 -> 9755246.2
A21: 15 | B21: MYL202001049 | C21: MR BOUNPON | D21: 2078916853 | E21: Production manager 02 | F21: ພາຍໃນປະເທດ | G21: 26 | H21: 4000000 | I21: =SUMIF($B$7:$B$175,OT!B22,OT!$S$8:$S$160) -> 0 | J21: =SUMIF($B$7:$B$136,เงินกะ!B22,เงินกะ!$M$8:$M$100) -> 0 | R21: 4000000 | S21: =400000/26*25 -> 384615.38 | T21: =SUM(H21:S21) -> 8384615.4 | V21: =SUMIF($B$7:$B$136,'ขาด-ลา-มาสาย'!B22,'ขาด-ลา-มาสาย'!$K$8:$K$100) -> 0 | W21: =SUMIF($B$7:$B$136,'ขาด-ลา-มาสาย'!B22,'ขาด-ลา-มาสาย'!$N$8:$N$100) -> 0 | X21: =SUMIF($B$7:$B$136,'ขาด-ลา-มาสาย'!B22,'ขาด-ลา-มาสาย'!$Q$8:$Q$100) -> 0 | Y21: =SUMIF($B$7:$B$136,'ขาด-ลา-มาสาย'!B22,'ขาด-ลา-มาสาย'!$T$8:$T$100) -> 0 | Z21: =SUMIF($B$7:$B$136,'ขาด-ลา-มาสาย'!B22,'ขาด-ลา-มาสาย'!$W$8:$W$100) -> 0 | AA21: =SUM(U21:Z21) -> 0 | AB21: =T21-AA21 -> 8384615.4 | AC21: =AB21-200000 -> 8184615.4 | AD21: =AC21*5% -> 409230.77 | AE21: =AB21-AD21 -> 7975384.6 | AG21: =AE21-AF21 -> 7975384.6 | AH21: PD | AI21: =AE21/680 -> 11728.507 | AK21: 034-8-02-00-00072 | AL21: =H21 -> 4000000 | AM21: =AA21 -> 0 | AN21: =AL21-AM21 -> 4000000 | AO21: =SUM(I21:S21) -> 4384615.4 | AP21: =AE21 -> 7975384.6
A22: 16 | B22: MYL000009 | C22: MR SONE | E22: Security Staff | F22: ພາຍໃນປະເທດ | G22: 26 | H22: =15500*680.67 -> 10550385 | I22: =SUMIF($B$7:$B$175,OT!B23,OT!$S$8:$S$160) -> 0 | J22: =SUMIF($B$7:$B$136,เงินกะ!B23,เงินกะ!$M$8:$M$100) -> 0 | T22: =SUM(H22:S22) -> 10550385 | V22: =SUMIF($B$7:$B$136,'ขาด-ลา-มาสาย'!B23,'ขาด-ลา-มาสาย'!$K$8:$K$100) -> 0 | W22: =SUMIF($B$7:$B$136,'ขาด-ลา-มาสาย'!B23,'ขาด-ลา-มาสาย'!$N$8:$N$100) -> 0 | X22: =SUMIF($B$7:$B$136,'ขาด-ลา-มาสาย'!B23,'ขาด-ลา-มาสาย'!$Q$8:$Q$100) -> 0 | Y22: =SUMIF($B$7:$B$136,'ขาด-ลา-มาสาย'!B23,'ขาด-ลา-มาสาย'!$T$8:$T$100) -> 0 | Z22: =SUMIF($B$7:$B$136,'ขาด-ลา-มาสาย'!B23,'ขาด-ลา-มาสาย'!$W$8:$W$100) -> 0 | AA22: =SUM(U22:Z22) -> 0 | AB22: =T22-AA22 -> 10550385 | AC22: =AB22-200000 -> 10350385 | AD22: =AC22*5% -> 517519.25 | AE22: =AB22-AD22 -> 10032866 | AG22: =AE22-AF22 -> 10032866 | AH22: PD | AI22: =AE22/680 -> 14754.214 | AK22: NO ACCOUNT | AL22: =H22 -> 10550385 | AM22: =AA22 -> 0 | AN22: =AL22-AM22 -> 10550385 | AO22: =SUM(I22:S22) -> 0 | AP22: =AE22 -> 10032866
A23: 17 | B23: MYL202401027 | C23: MRS NIK CHANTHANET | D23: 2056339678 | E23: Maid Staff | F23: ພາຍໃນປະເທດ | G23: 26 | H23: 2702000 | I23: =SUMIF($B$7:$B$175,OT!B24,OT!$S$8:$S$160) -> 0 | J23: =SUMIF($B$7:$B$136,เงินกะ!B24,เงินกะ!$M$8:$M$100) -> 0 | N23: 350000 | O23: 150000 | P23: 300000 | R23: 250000 | S23: =400000/26*25.5 -> 392307.69 | T23: =SUM(H23:S23) -> 4144307.7 | V23: =SUMIF($B$7:$B$136,'ขาด-ลา-มาสาย'!B24,'ขาด-ลา-มาสาย'!$K$8:$K$100) -> 0 | W23: =SUMIF($B$7:$B$136,'ขาด-ลา-มาสาย'!B24,'ขาด-ลา-มาสาย'!$N$8:$N$100) -> 0 | X23: =SUMIF($B$7:$B$136,'ขาด-ลา-มาสาย'!B24,'ขาด-ลา-มาสาย'!$Q$8:$Q$100) -> 0 | Y23: =SUMIF($B$7:$B$136,'ขาด-ลา-มาสาย'!B24,'ขาด-ลา-มาสาย'!$T$8:$T$100) -> 0 | Z23: =SUMIF($B$7:$B$136,'ขาด-ลา-มาสาย'!B24,'ขาด-ลา-มาสาย'!$W$8:$W$100) -> 0 | AA23: =SUM(U23:Z23) -> 0 | AB23: =T23-AA23 -> 4144307.7 | AC23: =AB23-200000 -> 3944307.7 | AD23: =AC23*5% -> 197215.38 | AE23: =AB23-AD23 -> 3947092.3 | AG23: =AE23-AF23 -> 3947092.3 | AH23: OF | AI23: =AE23/680 -> 5804.5475 | AK23: 034-0-02-00-00108 | AL23: =H23 -> 2702000 | AM23: =AA23 -> 0 | AN23: =AL23-AM23 -> 2702000 | AO23: =SUM(I23:S23) -> 1442307.7 | AP23: =AE23 -> 3947092.3
A24: 18 | B24: MYL201908028 | C24: MR TERY KHAMKOUNA | D24: 02059103026 | E24: Engineering | F24: ພາຍໃນປະເທດ | G24: 26 | H24: 5000000 | I24: =SUMIF($B$7:$B$175,OT!B25,OT!$S$8:$S$160) -> 0 | J24: =SUMIF($B$7:$B$136,เงินกะ!B25,เงินกะ!$M$8:$M$100) -> 0 | R24: 3500000 | S24: =400000/26*24 -> 369230.77 | T24: =SUM(H24:S24) -> 8869230.8 | U24: 88000 | V24: =SUMIF($B$7:$B$136,'ขาด-ลา-มาสาย'!B25,'ขาด-ลา-มาสาย'!$K$8:$K$100) -> 90000 | W24: =SUMIF($B$7:$B$136,'ขาด-ลา-มาสาย'!B25,'ขาด-ลา-มาสาย'!$N$8:$N$100) -> 0 | X24: =SUMIF($B$7:$B$136,'ขาด-ลา-มาสาย'!B25,'ขาด-ลา-มาสาย'!$Q$8:$Q$100) -> 0 | Y24: =SUMIF($B$7:$B$136,'ขาด-ลา-มาสาย'!B25,'ขาด-ลา-มาสาย'!$T$8:$T$100) -> 192307.69 | Z24: =SUMIF($B$7:$B$136,'ขาด-ลา-มาสาย'!B25,'ขาด-ลา-มาสาย'!$W$8:$W$100) -> 0 | AA24: =SUM(U24:Z24) -> 370307.69 | AB24: =T24-AA24 -> 8498923.1 | AC24: =AB24-200000 -> 8298923.1 | AD24: =AC24*5% -> 414946.15 | AE24: =AB24-AD24 -> 8083976.9 | AG24: =AE24-AF24 -> 8083976.9 | AH24: PD | AI24: =AE24/680 -> 11888.201 | AK24: 034-1-02-00-00059 | AL24: =H24 -> 5000000 | AM24: =AA24 -> 370307.69 | AN24: =AL24-AM24 -> 4629692.3 | AO24: =SUM(I24:S24) -> 3869230.8 | AP24: =AE24 -> 8083976.9
A25: 19 | B25: MYL202507076 | C25: MR XAYSONGKHAM SOMSANITH | D25: 2056211706 | E25: Engineering | F25: ພາຍໃນປະເທດ | G25: 26 | H25: 4500000 | I25: =SUMIF($B$7:$B$175,OT!B26,OT!$S$8:$S$160) -> 0 | J25: =SUMIF($B$7:$B$136,เงินกะ!B26,เงินกะ!$M$8:$M$100) -> 0 | R25: 2500000 | S25: 400000 | T25: =SUM(H25:S25) -> 7400000 | V25: =SUMIF($B$7:$B$136,'ขาด-ลา-มาสาย'!B26,'ขาด-ลา-มาสาย'!$K$8:$K$100) -> 50000 | W25: =SUMIF($B$7:$B$136,'ขาด-ลา-มาสาย'!B26,'ขาด-ลา-มาสาย'!$N$8:$N$100) -> 0 | X25: =SUMIF($B$7:$B$136,'ขาด-ลา-มาสาย'!B26,'ขาด-ลา-มาสาย'!$Q$8:$Q$100) -> 0 | Y25: =SUMIF($B$7:$B$136,'ขาด-ลา-มาสาย'!B26,'ขาด-ลา-มาสาย'!$T$8:$T$100) -> 0 | Z25: =SUMIF($B$7:$B$136,'ขาด-ลา-มาสาย'!B26,'ขาด-ลา-มาสาย'!$W$8:$W$100) -> 0 | AA25: =SUM(U25:Z25) -> 50000 | AB25: =T25-AA25 -> 7350000 | AC25: =AB25-200000 -> 7150000 | AD25: =AC25*5% -> 357500 | AE25: =AB25-AD25 -> 6992500 | AG25: =AE25-AF25 -> 6992500 | AH25: OF | AI25: =AE25/680 -> 10283.088 | AK25: 034-9-02-00-00398 | AL25: =H25 -> 4500000 | AM25: =AA25 -> 50000 | AN25: =AL25-AM25 -> 4450000 | AO25: =SUM(I25:S25) -> 2900000 | AP25: =AE25 -> 6992500
A26: 20 | B26: MYL201908026 | C26: MR SONGKAN PHACHANSITTHI | D26: 2054612045 | E26: QC Manager 02 | F26: ພາຍໃນປະເທດ | G26: 26 | H26: 4000000 | I26: =SUMIF($B$7:$B$175,OT!B27,OT!$S$8:$S$160) -> 0 | J26: =SUMIF($B$7:$B$136,เงินกะ!B27,เงินกะ!$M$8:$M$100) -> 0 | R26: 4000000 | S26: =400000/26*23.5 -> 361538.46 | T26: =SUM(H26:S26) -> 8361538.5 | V26: =SUMIF($B$7:$B$136,'ขาด-ลา-มาสาย'!B27,'ขาด-ลา-มาสาย'!$K$8:$K$100) -> 0 | W26: =SUMIF($B$7:$B$136,'ขาด-ลา-มาสาย'!B27,'ขาด-ลา-มาสาย'!$N$8:$N$100) -> 0 | X26: =SUMIF($B$7:$B$136,'ขาด-ลา-มาสาย'!B27,'ขาด-ลา-มาสาย'!$Q$8:$Q$100) -> 0 | Y26: =SUMIF($B$7:$B$136,'ขาด-ลา-มาสาย'!B27,'ขาด-ลา-มาสาย'!$T$8:$T$100) -> 0 | Z26: =SUMIF($B$7:$B$136,'ขาด-ลา-มาสาย'!B27,'ขาด-ลา-มาสาย'!$W$8:$W$100) -> 0 | AA26: =SUM(U26:Z26) -> 0 | AB26: =T26-AA26 -> 8361538.5 | AC26: =AB26-200000 -> 8161538.5 | AD26: =AC26*5% -> 408076.92 | AE26: =AB26-AD26 -> 7953461.5 | AG26: =AE26-AF26 -> 7953461.5 | AH26: OF | AI26: =AE26/680 -> 11696.267 | AK26: 030-0-00-00-05978 | AL26: =H26 -> 4000000 | AM26: =AA26 -> 0 | AN26: =AL26-AM26 -> 4000000 | AO26: =SUM(I26:S26) -> 4361538.5 | AP26: =AE26 -> 7953461.5
A27: 21 | B27: MYL202504064 | C27: MISS NALIN SYHALATH | D27: 2098953256 | E27: QC PTS | F27: ພາຍໃນປະເທດ | G27: 26 | H27: 2600000 | I27: =SUMIF($B$7:$B$175,OT!B28,OT!$S$8:$S$160) -> 0 | J27: =SUMIF($B$7:$B$136,เงินกะ!B28,เงินกะ!$M$8:$M$100) -> 0 | O27: 150000 | P27: 150000 | Q27: 200000 | R27: 600000 | S27: =400000/26*18.5 -> 284615.38 | T27: =SUM(H27:S27) -> 3984615.4 | V27: =SUMIF($B$7:$B$136,'ขาด-ลา-มาสาย'!B28,'ขาด-ลา-มาสาย'!$K$8:$K$100) -> 0 | W27: =SUMIF($B$7:$B$136,'ขาด-ลา-มาสาย'!B28,'ขาด-ลา-มาสาย'!$N$8:$N$100) -> 20000 | X27: =SUMIF($B$7:$B$136,'ขาด-ลา-มาสาย'!B28,'ขาด-ลา-มาสาย'!$Q$8:$Q$100) -> 0 | Y27: =SUMIF($B$7:$B$136,'ขาด-ลา-มาสาย'!B28,'ขาด-ลา-มาสาย'!$T$8:$T$100) -> 200000 | Z27: =SUMIF($B$7:$B$136,'ขาด-ลา-มาสาย'!B28,'ขาด-ลา-มาสาย'!$W$8:$W$100) -> 0 | AA27: =SUM(U27:Z27) -> 220000 | AB27: =T27-AA27 -> 3764615.4 | AC27: =AB27-200000 -> 3564615.4 | AD27: =AC27*5% -> 178230.77 | AE27: =AB27-AD27 -> 3586384.6 | AG27: =AE27-AF27 -> 3586384.6 | AH27: PD | AI27: =AE27/680 -> 5274.095 | AK27: 030-3-02-00-12401 | AL27: =H27 -> 2600000 | AM27: =AA27 -> 220000 | AN27: =AL27-AM27 -> 2380000 | AO27: =SUM(I27:S27) -> 1384615.4 | AP27: =AE27 -> 3586384.6
A28: 22 | B28: MYL202606160 | C28: MISS LAMPHAI THUMMAVONGE | D28: 2091381527 | E28: QC SAS | F28: ພາຍໃນປະເທດ | G28: 26 | H28: 2500000 | I28: =SUMIF($B$7:$B$175,OT!B29,OT!$S$8:$S$160) -> 0 | J28: =SUMIF($B$7:$B$136,เงินกะ!B29,เงินกะ!$M$8:$M$100) -> 0 | K28: 0 | O28: =150000/26*10 -> 57692.308 | P28: =150000/26*10 -> 57692.308 | Q28: =200000/26*10 -> 76923.077 | R28: =600000/26*10 -> 230769.23 | S28: =400000/26*10 -> 153846.15 | T28: =SUM(H28:S28) -> 3076923.1 | V28: =SUMIF($B$7:$B$136,'ขาด-ลา-มาสาย'!B29,'ขาด-ลา-มาสาย'!$K$8:$K$100) -> 10000 | W28: =SUMIF($B$7:$B$136,'ขาด-ลา-มาสาย'!B29,'ขาด-ลา-มาสาย'!$N$8:$N$100) -> 0 | X28: =SUMIF($B$7:$B$136,'ขาด-ลา-มาสาย'!B29,'ขาด-ลา-มาสาย'!$Q$8:$Q$100) -> 0 | Y28: =SUMIF($B$7:$B$136,'ขาด-ลา-มาสาย'!B29,'ขาด-ลา-มาสาย'!$T$8:$T$100) -> 192307.69 | Z28: =SUMIF($B$7:$B$136,'ขาด-ลา-มาสาย'!B29,'ขาด-ลา-มาสาย'!$W$8:$W$100) -> 1346153.8 | AA28: =SUM(U28:Z28) -> 1548461.5 | AB28: =T28-AA28 -> 1528461.5 | AC28: =AB28-200000 -> 1328461.5 | AD28: =AC28*5% -> 66423.077 | AE28: =AB28-AD28 -> 1462038.5 | AG28: =AE28-AF28 -> 1462038.5
A29: 23 | B29: MYL202301037 | C29: MRS PHOULATSAMY SETTHATHILATH | D29: 2077074510 | E29: STORE PTS | F29: ພາຍໃນປະເທດ | G29: 26 | H29: 3300000 | I29: =SUMIF($B$7:$B$175,OT!B30,OT!$S$8:$S$160) -> 0 | J29: =SUMIF($B$7:$B$136,เงินกะ!B30,เงินกะ!$M$8:$M$100) -> 0 | L29: 200000 | O29: 150000 | P29: 150000 | R29: 1700000 | T29: =SUM(H29:S29) -> 5500000 | U29: 88000 | V29: =SUMIF($B$7:$B$136,'ขาด-ลา-มาสาย'!B30,'ขาด-ลา-มาสาย'!$K$8:$K$100) -> 0 | W29: =SUMIF($B$7:$B$136,'ขาด-ลา-มาสาย'!B30,'ขาด-ลา-มาสาย'!$N$8:$N$100) -> 0 | X29: =SUMIF($B$7:$B$136,'ขาด-ลา-มาสาย'!B30,'ขาด-ลา-มาสาย'!$Q$8:$Q$100) -> 0 | Y29: =SUMIF($B$7:$B$136,'ขาด-ลา-มาสาย'!B30,'ขาด-ลา-มาสาย'!$T$8:$T$100) -> 0 | Z29: =SUMIF($B$7:$B$136,'ขาด-ลา-มาสาย'!B30,'ขาด-ลา-มาสาย'!$W$8:$W$100) -> 0 | AA29: =SUM(U29:Z29) -> 88000 | AB29: =T29-AA29 -> 5412000 | AC29: =AB29-200000 -> 5212000 | AD29: =AC29*5% -> 260600 | AE29: =AB29-AD29 -> 5151400 | AG29: =AE29-AF29 -> 5151400 | AH29: PD | AI29: =AE29/680 -> 7575.5882 | AK29: 034-3-02-00-00226 | AL29: =H29 -> 3300000 | AM29: =AA29 -> 88000 | AN29: =AL29-AM29 -> 3212000 | AO29: =SUM(I29:S29) -> 2200000 | AP29: =AE29 -> 5151400
A30: 24 | B30: MYT202602133 | C30: MR BOUNTHAVY KOMKAIYASONE | D30: 2097221714 | E30: STORE PTS | F30: ພາຍໃນປະເທດ | G30: 26 | H30: 2600000 | I30: =SUMIF($B$7:$B$175,OT!B31,OT!$S$8:$S$160) -> 0 | J30: =SUMIF($B$7:$B$136,เงินกะ!B31,เงินกะ!$M$8:$M$100) -> 0 | K30: 300000 | O30: 150000 | P30: 150000 | Q30: 200000 | R30: 400000 | S30: =400000/26*24 -> 369230.77 | T30: =SUM(H30:S30) -> 4169230.8 | V30: =SUMIF($B$7:$B$136,'ขาด-ลา-มาสาย'!B31,'ขาด-ลา-มาสาย'!$K$8:$K$100) -> 0 | W30: =SUMIF($B$7:$B$136,'ขาด-ลา-มาสาย'!B31,'ขาด-ลา-มาสาย'!$N$8:$N$100) -> 0 | X30: =SUMIF($B$7:$B$136,'ขาด-ลา-มาสาย'!B31,'ขาด-ลา-มาสาย'!$Q$8:$Q$100) -> 0 | Y30: =SUMIF($B$7:$B$136,'ขาด-ลา-มาสาย'!B31,'ขาด-ลา-มาสาย'!$T$8:$T$100) -> 200000 | Z30: =SUMIF($B$7:$B$136,'ขาด-ลา-มาสาย'!B31,'ขาด-ลา-มาสาย'!$W$8:$W$100) -> 0 | AA30: =SUM(U30:Z30) -> 200000 | AB30: =T30-AA30 -> 3969230.8 | AC30: =AB30-200000 -> 3769230.8 | AD30: =AC30*5% -> 188461.54 | AE30: =AB30-AD30 -> 3780769.2 | AG30: =AE30-AF30 -> 3780769.2 | AH30: PD | AI30: =AE30/680 -> 5559.9548 | AK30: NO ACCOUNT | AL30: =H30 -> 2600000 | AM30: =AA30 -> 200000 | AN30: =AL30-AM30 -> 2400000 | AO30: =SUM(I30:S30) -> 1569230.8 | AP30: =AE30 -> 3780769.2
A31: 25 | B31: MYL202404006 | C31: MR SENGMANY PHATTHANA | D31: 2059597282 | E31: STORE OTS | F31: ພາຍໃນປະເທດ | G31: 26 | H31: 3300000 | I31: =SUMIF($B$7:$B$175,OT!B32,OT!$S$8:$S$160) -> 23798.077 | J31: =SUMIF($B$7:$B$136,เงินกะ!B32,เงินกะ!$M$8:$M$100) -> 36490.385 | L31: 200000 | O31: 150000 | Q31: 200000 | R31: 1700000 | S31: =200000/26*22 -> 169230.77 | T31: =SUM(H31:S31) -> 5779519.2 | V31: =SUMIF($B$7:$B$136,'ขาด-ลา-มาสาย'!B32,'ขาด-ลา-มาสาย'!$K$8:$K$100) -> 0 | W31: =SUMIF($B$7:$B$136,'ขาด-ลา-มาสาย'!B32,'ขาด-ลา-มาสาย'!$N$8:$N$100) -> 0 | X31: =SUMIF($B$7:$B$136,'ขาด-ลา-มาสาย'!B32,'ขาด-ลา-มาสาย'!$Q$8:$Q$100) -> 0 | Y31: =SUMIF($B$7:$B$136,'ขาด-ลา-มาสาย'!B32,'ขาด-ลา-มาสาย'!$T$8:$T$100) -> 507692.31 | Z31: =SUMIF($B$7:$B$136,'ขาด-ลา-มาสาย'!B32,'ขาด-ลา-มาสาย'!$W$8:$W$100) -> 0 | AA31: =SUM(U31:Z31) -> 507692.31 | AB31: =T31-AA31 -> 5271826.9 | AC31: =AB31-200000 -> 5071826.9 | AD31: =AC31*5% -> 253591.35 | AE31: =AB31-AD31 -> 5018235.6 | AG31: =AE31-AF31 -> 5018235.6 | AH31: PD | AI31: =AE31/680 -> 7379.7582 | AK31: 034-9-02-00-00376 | AL31: =H31 -> 3300000 | AM31: =AA31 -> 507692.31 | AN31: =AL31-AM31 -> 2792307.7 | AO31: =SUM(I31:S31) -> 2479519.2 | AP31: =AE31 -> 5018235.6
A32: 26 | B32: MYL202601128 | C32: MR KHAMPHASITH XAYYAJACK | D32: 2077412771 | E32: STORE OTS | F32: ພາຍໃນປະເທດ | G32: 26 | H32: 2600000 | I32: =SUMIF($B$7:$B$175,OT!B33,OT!$S$8:$S$160) -> 37500 | J32: =SUMIF($B$7:$B$136,เงินกะ!B33,เงินกะ!$M$8:$M$100) -> 0 | K32: =300000/26*12 -> 138461.54 | L32: 0 | N32: 0 | O32: =150000/26*12 -> 69230.769 | P32: =150000/26*12 -> 69230.769 | Q32: =200000/26*12 -> 92307.692 | R32: =400000/26*12 -> 184615.38 | S32: =400000/26*12 -> 184615.38 | T32: =SUM(H32:S32) -> 3375961.5 | V32: =SUMIF($B$7:$B$136,'ขาด-ลา-มาสาย'!B33,'ขาด-ลา-มาสาย'!$K$8:$K$100) -> 0 | W32: =SUMIF($B$7:$B$136,'ขาด-ลา-มาสาย'!B33,'ขาด-ลา-มาสาย'!$N$8:$N$100) -> 0 | X32: =SUMIF($B$7:$B$136,'ขาด-ลา-มาสาย'!B33,'ขาด-ลา-มาสาย'!$Q$8:$Q$100) -> 0 | Y32: =SUMIF($B$7:$B$136,'ขาด-ลา-มาสาย'!B33,'ขาด-ลา-มาสาย'!$T$8:$T$100) -> 0 | Z32: =SUMIF($B$7:$B$136,'ขาด-ลา-มาสาย'!B33,'ขาด-ลา-มาสาย'!$W$8:$W$100) -> 1200000 | AA32: =SUM(U32:Z32) -> 1200000 | AB32: =T32-AA32 -> 2175961.5 | AC32: =AB32-200000 -> 1975961.5 | AD32: =AC32*5% -> 98798.077 | AE32: =AB32-AD32 -> 2077163.5 | AG32: =AE32-AF32 -> 2077163.5 | AH32: PD | AI32: =AE32/680 -> 3054.6521 | AK32: NO ACCOUNT | AL32: =H32 -> 2600000 | AM32: =AA32 -> 1200000 | AN32: =AL32-AM32 -> 1400000 | AO32: =SUM(I32:S32) -> 775961.54 | AP32: =AE32 -> 2077163.5
A33: 27 | B33: MYL202606162 | C33: MISS KHONESAVANH CHANTHALAY | D33: 2096532048 | E33: STORE OTS | F33: ພາຍໃນປະເທດ | G33: 26 | H33: 2500000 | I33: =SUMIF($B$7:$B$175,OT!B34,OT!$S$8:$S$160) -> 0 | J33: =SUMIF($B$7:$B$136,เงินกะ!B34,เงินกะ!$M$8:$M$100) -> 0 | K33: =300000/26*12 -> 138461.54 | L33: =200000/26*12 -> 92307.692 | N33: =250000/26*12 -> 115384.62 | O33: =150000/26*12 -> 69230.769 | P33: =150000/26*12 -> 69230.769 | Q33: =200000/26*12 -> 92307.692 | R33: =300000/26*12 -> 138461.54 | S33: =400000/26*12 -> 184615.38 | T33: =SUM(H33:S33) -> 3400000 | V33: =SUMIF($B$7:$B$136,'ขาด-ลา-มาสาย'!B34,'ขาด-ลา-มาสาย'!$K$8:$K$100) -> 0 | W33: =SUMIF($B$7:$B$136,'ขาด-ลา-มาสาย'!B34,'ขาด-ลา-มาสาย'!$N$8:$N$100) -> 0 | X33: =SUMIF($B$7:$B$136,'ขาด-ลา-มาสาย'!B34,'ขาด-ลา-มาสาย'!$Q$8:$Q$100) -> 0 | Y33: =SUMIF($B$7:$B$136,'ขาด-ลา-มาสาย'!B34,'ขาด-ลา-มาสาย'!$T$8:$T$100) -> 0 | Z33: =SUMIF($B$7:$B$136,'ขาด-ลา-มาสาย'!B34,'ขาด-ลา-มาสาย'!$W$8:$W$100) -> 1346153.8 | AA33: =SUM(U33:Z33) -> 1346153.8 | AB33: =T33-AA33 -> 2053846.2 | AC33: =AB33-200000 -> 1853846.2 | AD33: =AC33*5% -> 92692.308 | AE33: =AB33-AD33 -> 1961153.8 | AG33: =AE33-AF33 -> 1961153.8
A34: 28 | B34: MYL202001035 | C34: MRS TOUKTA PONGSIMMALY | D34: 2057706864 | E34: STORE SAS | F34: ພາຍໃນປະເທດ | G34: 26 | H34: 3300000 | I34: =SUMIF($B$7:$B$175,OT!B35,OT!$S$8:$S$160) -> 23798.077 | J34: =SUMIF($B$7:$B$136,เงินกะ!B35,เงินกะ!$M$8:$M$100) -> 0 | L34: 200000 | N34: 250000 | O34: 150000 | P34: 150000 | Q34: 200000 | R34: 1700000 | S34: 400000 | T34: =SUM(H34:S34) -> 6373798.1 | U34: 88000 | V34: =SUMIF($B$7:$B$136,'ขาด-ลา-มาสาย'!B35,'ขาด-ลา-มาสาย'!$K$8:$K$100) -> 0 | W34: =SUMIF($B$7:$B$136,'ขาด-ลา-มาสาย'!B35,'ขาด-ลา-มาสาย'!$N$8:$N$100) -> 0 | X34: =SUMIF($B$7:$B$136,'ขาด-ลา-มาสาย'!B35,'ขาด-ลา-มาสาย'!$Q$8:$Q$100) -> 0 | Y34: =SUMIF($B$7:$B$136,'ขาด-ลา-มาสาย'!B35,'ขาด-ลา-มาสาย'!$T$8:$T$100) -> 0 | Z34: =SUMIF($B$7:$B$136,'ขาด-ลา-มาสาย'!B35,'ขาด-ลา-มาสาย'!$W$8:$W$100) -> 0 | AA34: =SUM(U34:Z34) -> 88000 | AB34: =T34-AA34 -> 6285798.1 | AC34: =AB34-200000 -> 6085798.1 | AD34: =AC34*5% -> 304289.9 | AE34: =AB34-AD34 -> 5981508.2 | AG34: =AE34-AF34 -> 5981508.2 | AH34: PD | AI34: =AE34/680 -> 8796.3355 | AK34: 034-7-02-00-00121 | AL34: =H34 -> 3300000 | AM34: =AA34 -> 88000 | AN34: =AL34-AM34 -> 3212000 | AO34: =SUM(I34:S34) -> 3073798.1 | AP34: =AE34 -> 5981508.2
A35: 29 | B35: MYL202605151 | C35: MR SOULIYA | D35: 2099427578 | E35: STORE SAS | F35: ພາຍໃນປະເທດ | G35: 26 | H35: 2600000 | I35: =SUMIF($B$7:$B$175,OT!B36,OT!$S$8:$S$160) -> 0 | J35: =SUMIF($B$7:$B$136,เงินกะ!B36,เงินกะ!$M$8:$M$100) -> 0 | K35: =300000/26*11 -> 126923.08 | O35: 0 | P35: =150000/26*11 -> 63461.538 | R35: =300000/26*11 -> 126923.08 | S35: =400000/26*11 -> 169230.77 | T35: =SUM(H35:S35) -> 3086538.5 | V35: =SUMIF($B$7:$B$136,'ขาด-ลา-มาสาย'!B36,'ขาด-ลา-มาสาย'!$K$8:$K$100) -> 50000 | W35: =SUMIF($B$7:$B$136,'ขาด-ลา-มาสาย'!B36,'ขาด-ลา-มาสาย'!$N$8:$N$100) -> 0 | X35: =SUMIF($B$7:$B$136,'ขาด-ลา-มาสาย'!B36,'ขาด-ลา-มาสาย'!$Q$8:$Q$100) -> 0 | Y35: =SUMIF($B$7:$B$136,'ขาด-ลา-มาสาย'!B36,'ขาด-ลา-มาสาย'!$T$8:$T$100) -> 200000 | Z35: =SUMIF($B$7:$B$136,'ขาด-ลา-มาสาย'!B36,'ขาด-ลา-มาสาย'!$W$8:$W$100) -> 1700000 | AA35: =SUM(U35:Z35) -> 1950000 | AB35: =T35-AA35 -> 1136538.5 | AC35: =AB35-200000 -> 936538.46 | AD35: =AC35*5% -> 46826.923 | AE35: =AB35-AD35 -> 1089711.5 | AG35: =AE35-AF35 -> 1089711.5 | AH35: PD | AI35: =AE35/680 -> 1602.517 | AK35: NO ACCOUNT | AL35: =H35 -> 2600000 | AM35: =AA35 -> 1950000 | AN35: =AL35-AM35 -> 650000 | AO35: =SUM(I35:S35) -> 486538.46 | AP35: =AE35 -> 1089711.5
A36: 30 | B36: MYL202201050 | C36: MR TOUTONNAM KHOUNSAVANH | D36: 2093949318 | E36: Welding PTS | F36: ພາຍໃນປະເທດ | G36: 26 | H36: 3300000 | I36: =SUMIF($B$7:$B$175,OT!B37,OT!$S$8:$S$160) -> 0 | J36: =SUMIF($B$7:$B$136,เงินกะ!B37,เงินกะ!$M$8:$M$100) -> 0 | K36: =H36*15% -> 495000 | L36: 200000 | O36: 150000 | P36: 150000 | Q36: 200000 | R36: 1700000 | S36: 400000 | T36: =SUM(H36:S36) -> 6595000 | V36: =SUMIF($B$7:$B$136,'ขาด-ลา-มาสาย'!B37,'ขาด-ลา-มาสาย'!$K$8:$K$100) -> 10000 | W36: =SUMIF($B$7:$B$136,'ขาด-ลา-มาสาย'!B37,'ขาด-ลา-มาสาย'!$N$8:$N$100) -> 0 | X36: =SUMIF($B$7:$B$136,'ขาด-ลา-มาสาย'!B37,'ขาด-ลา-มาสาย'!$Q$8:$Q$100) -> 0 | Y36: =SUMIF($B$7:$B$136,'ขาด-ลา-มาสาย'!B37,'ขาด-ลา-มาสาย'!$T$8:$T$100) -> 0 | Z36: =SUMIF($B$7:$B$136,'ขาด-ลา-มาสาย'!B37,'ขาด-ลา-มาสาย'!$W$8:$W$100) -> 0 | AA36: =SUM(U36:Z36) -> 10000 | AB36: =T36-AA36 -> 6585000 | AC36: =AB36-200000 -> 6385000 | AD36: =AC36*5% -> 319250 | AE36: =AB36-AD36 -> 6265750 | AG36: =AE36-AF36 -> 6265750 | AH36: PD | AI36: =AE36/680 -> 9214.3382 | AK36: 034-2-02-00-00212 | AL36: =H36 -> 3300000 | AM36: =AA36 -> 10000 | AN36: =AL36-AM36 -> 3290000 | AO36: =SUM(I36:S36) -> 3295000 | AP36: =AE36 -> 6265750
A37: 31 | B37: MYL202502061 | C37: MR KHONESAVANH SYTHAVONG | D37: 2096870409 | E37: Welding PTS | F37: ພາຍໃນປະເທດ | G37: 26 | H37: 2600000 | I37: =SUMIF($B$7:$B$175,OT!B38,OT!$S$8:$S$160) -> 0 | J37: =SUMIF($B$7:$B$136,เงินกะ!B38,เงินกะ!$M$8:$M$100) -> 0 | K37: =H37*15%/26*17.5 -> 262500 | O37: =150000/26*17.5 -> 100961.54 | P37: =150000/26*17.5 -> 100961.54 | Q37: =200000/26*17.5 -> 134615.38 | R37: =1000000/26*17.5 -> 673076.92 | S37: =400000/26*17.5 -> 269230.77 | T37: =SUM(H37:S37) -> 4141346.2 | V37: =SUMIF($B$7:$B$136,'ขาด-ลา-มาสาย'!B38,'ขาด-ลา-มาสาย'!$K$8:$K$100) -> 0 | W37: =SUMIF($B$7:$B$136,'ขาด-ลา-มาสาย'!B38,'ขาด-ลา-มาสาย'!$N$8:$N$100) -> 0 | X37: =SUMIF($B$7:$B$136,'ขาด-ลา-มาสาย'!B38,'ขาด-ลา-มาสาย'!$Q$8:$Q$100) -> 50000 | Y37: =SUMIF($B$7:$B$136,'ขาด-ลา-มาสาย'!B38,'ขาด-ลา-มาสาย'!$T$8:$T$100) -> 450000 | Z37: =SUMIF($B$7:$B$136,'ขาด-ลา-มาสาย'!B38,'ขาด-ลา-มาสาย'!$W$8:$W$100) -> 400000 | AA37: =SUM(U37:Z37) -> 900000 | AB37: =T37-AA37 -> 3241346.2 | AC37: =AB37-200000 -> 3041346.2 | AD37: =AC37*5% -> 152067.31 | AE37: =AB37-AD37 -> 3089278.8 | AG37: =AE37-AF37 -> 3089278.8 | AI37: 0 | AK37: 030-6-02-00-12411 | AL37: =H37 -> 2600000 | AM37: =AA37 -> 900000 | AN37: =AL37-AM37 -> 1700000 | AO37: =SUM(I37:S37) -> 1541346.2 | AP37: =AE37 -> 3089278.8
A38: 32 | B38: MYL202504072 | C38: MR BACKHAM XAISONGKHAM | D38: 2093768539 | E38: Welding PTS | F38: ພາຍໃນປະເທດ | G38: 26 | H38: 2600000 | I38: =SUMIF($B$7:$B$175,OT!B39,OT!$S$8:$S$160) -> 0 | J38: =SUMIF($B$7:$B$136,เงินกะ!B39,เงินกะ!$M$8:$M$100) -> 0 | K38: =H38*15% -> 390000 | L38: 200000 | N38: 250000 | O38: 150000 | P38: 150000 | Q38: 200000 | R38: 1000000 | S38: =400000/26*24 -> 369230.77 | T38: =SUM(H38:S38) -> 5309230.8 | V38: =SUMIF($B$7:$B$136,'ขาด-ลา-มาสาย'!B39,'ขาด-ลา-มาสาย'!$K$8:$K$100) -> 0 | W38: =SUMIF($B$7:$B$136,'ขาด-ลา-มาสาย'!B39,'ขาด-ลา-มาสาย'!$N$8:$N$100) -> 0 | X38: =SUMIF($B$7:$B$136,'ขาด-ลา-มาสาย'!B39,'ขาด-ลา-มาสาย'!$Q$8:$Q$100) -> 0 | Y38: =SUMIF($B$7:$B$136,'ขาด-ลา-มาสาย'!B39,'ขาด-ลา-มาสาย'!$T$8:$T$100) -> 0 | Z38: =SUMIF($B$7:$B$136,'ขาด-ลา-มาสาย'!B39,'ขาด-ลา-มาสาย'!$W$8:$W$100) -> 0 | AA38: =SUM(U38:Z38) -> 0 | AB38: =T38-AA38 -> 5309230.8 | AC38: =AB38-200000 -> 5109230.8 | AD38: =AC38*5% -> 255461.54 | AE38: =AB38-AD38 -> 5053769.2 | AG38: =AE38-AF38 -> 5053769.2 | AH38: PD | AI38: =AE38/680 -> 7432.0136 | AK38: NO ACCOUNT | AL38: =H38 -> 2600000 | AM38: =AA38 -> 0 | AN38: =AL38-AM38 -> 2600000 | AO38: =SUM(I38:S38) -> 2709230.8 | AP38: =AE38 -> 5053769.2
A39: 33 | B39: MYL202509108 | C39: MR SEEVA PONGSIMMALY | D39: 2056238018 | E39: Welding PTS | F39: ພາຍໃນປະເທດ | G39: 26 | H39: 2600000 | I39: =SUMIF($B$7:$B$175,OT!B40,OT!$S$8:$S$160) -> 0 | J39: =SUMIF($B$7:$B$136,เงินกะ!B40,เงินกะ!$M$8:$M$100) -> 0 | K39: =H39*15% -> 390000 | L39: 200000 | N39: 250000 | O39: 150000 | P39: 150000 | Q39: 200000 | R39: 1000000 | S39: 400000 | T39: =SUM(H39:S39) -> 5340000 | V39: =SUMIF($B$7:$B$136,'ขาด-ลา-มาสาย'!B40,'ขาด-ลา-มาสาย'!$K$8:$K$100) -> 0 | W39: =SUMIF($B$7:$B$136,'ขาด-ลา-มาสาย'!B40,'ขาด-ลา-มาสาย'!$N$8:$N$100) -> 0 | X39: =SUMIF($B$7:$B$136,'ขาด-ลา-มาสาย'!B40,'ขาด-ลา-มาสาย'!$Q$8:$Q$100) -> 0 | Y39: =SUMIF($B$7:$B$136,'ขาด-ลา-มาสาย'!B40,'ขาด-ลา-มาสาย'!$T$8:$T$100) -> 0 | Z39: =SUMIF($B$7:$B$136,'ขาด-ลา-มาสาย'!B40,'ขาด-ลา-มาสาย'!$W$8:$W$100) -> 0 | AA39: =SUM(U39:Z39) -> 0 | AB39: =T39-AA39 -> 5340000 | AC39: =AB39-200000 -> 5140000 | AD39: =AC39*5% -> 257000 | AE39: =AB39-AD39 -> 5083000 | AG39: =AE39-AF39 -> 5083000 | AH39: PD | AI39: =AE39/680 -> 7475 | AK39: NO ACCOUNT | AL39: =H39 -> 2600000 | AM39: =AA39 -> 0 | AN39: =AL39-AM39 -> 2600000 | AO39: =SUM(I39:S39) -> 2740000 | AP39: =AE39 -> 5083000
A40: 34 | B40: MYL202509109 | C40: MR YOD CHAMPA | D40: 2091295633 | E40: Welding PTS | F40: ພາຍໃນປະເທດ | G40: 26 | H40: 2600000 | I40: =SUMIF($B$7:$B$175,OT!B41,OT!$S$8:$S$160) -> 0 | J40: =SUMIF($B$7:$B$136,เงินกะ!B41,เงินกะ!$M$8:$M$100) -> 0 | K40: =H40*15%/26*24.5 -> 367500 | L40: 200000 | O40: 150000 | P40: 150000 | Q40: 200000 | R40: 1000000 | S40: =400000/26*23.5 -> 361538.46 | T40: =SUM(H40:S40) -> 5029038.5 | V40: =SUMIF($B$7:$B$136,'ขาด-ลา-มาสาย'!B41,'ขาด-ลา-มาสาย'!$K$8:$K$100) -> 10000 | W40: =SUMIF($B$7:$B$136,'ขาด-ลา-มาสาย'!B41,'ขาด-ลา-มาสาย'!$N$8:$N$100) -> 0 | X40: =SUMIF($B$7:$B$136,'ขาด-ลา-มาสาย'!B41,'ขาด-ลา-มาสาย'!$Q$8:$Q$100) -> 0 | Y40: =SUMIF($B$7:$B$136,'ขาด-ลา-มาสาย'!B41,'ขาด-ลา-มาสาย'!$T$8:$T$100) -> 150000 | Z40: =SUMIF($B$7:$B$136,'ขาด-ลา-มาสาย'!B41,'ขาด-ลา-มาสาย'!$W$8:$W$100) -> 0 | AA40: =SUM(U40:Z40) -> 160000 | AB40: =T40-AA40 -> 4869038.5 | AC40: =AB40-200000 -> 4669038.5 | AD40: =AC40*5% -> 233451.92 | AE40: =AB40-AD40 -> 4635586.5 | AG40: =AE40-AF40 -> 4635586.5 | AH40: PD | AI40: =AE40/680 -> 6817.039 | AK40: NO ACCOUNT | AL40: =H40 -> 2600000 | AM40: =AA40 -> 160000 | AN40: =AL40-AM40 -> 2440000 | AO40: =SUM(I40:S40) -> 2429038.5 | AP40: =AE40 -> 4635586.5
A41: 35 | B41: MYT202604143 | C41: MR BOUNSAVATH PHETKHAMBOONHUEANG | D41: 2099099712 | E41: Welding PTS | F41: ພາຍໃນປະເທດ | G41: 26 | H41: 2500000 | I41: =SUMIF($B$7:$B$175,OT!B42,OT!$S$8:$S$160) -> 0 | J41: =SUMIF($B$7:$B$136,เงินกะ!B42,เงินกะ!$M$8:$M$100) -> 0 | K41: =H41*15%/26*24 -> 346153.85 | L41: 200000 | O41: 150000 | P41: 150000 | Q41: 200000 | R41: 350000 | S41: =400000/26*25 -> 384615.38 | T41: =SUM(H41:S41) -> 4280769.2 | V41: =SUMIF($B$7:$B$136,'ขาด-ลา-มาสาย'!B42,'ขาด-ลา-มาสาย'!$K$8:$K$100) -> 0 | W41: =SUMIF($B$7:$B$136,'ขาด-ลา-มาสาย'!B42,'ขาด-ลา-มาสาย'!$N$8:$N$100) -> 0 | X41: =SUMIF($B$7:$B$136,'ขาด-ลา-มาสาย'!B42,'ขาด-ลา-มาสาย'!$Q$8:$Q$100) -> 0 | Y41: =SUMIF($B$7:$B$136,'ขาด-ลา-มาสาย'!B42,'ขาด-ลา-มาสาย'!$T$8:$T$100) -> 96153.846 | Z41: =SUMIF($B$7:$B$136,'ขาด-ลา-มาสาย'!B42,'ขาด-ลา-มาสาย'!$W$8:$W$100) -> 0 | AA41: =SUM(U41:Z41) -> 96153.846 | AB41: =T41-AA41 -> 4184615.4 | AC41: =AB41-200000 -> 3984615.4 | AD41: =AC41*5% -> 199230.77 | AE41: =AB41-AD41 -> 3985384.6 | AG41: =AE41-AF41 -> 3985384.6 | AH41: PD | AI41: =AE41/680 -> 5860.8597 | AK41: NO ACCOUNT | AL41: =H41 -> 2500000 | AM41: =AA41 -> 96153.846 | AN41: =AL41-AM41 -> 2403846.2 | AO41: =SUM(I41:S41) -> 1780769.2 | AP41: =AE41 -> 3985384.6
...

Sheet OT
L1: ສາທາລະນະລັດ ປະຊາທິປະໄຕ ປະຊາຊົນລາວ
L2: ສັນຕິພາບ ເອກະລາດ ປະຊາທິປະໄຕ ເອກະພາບ ວັດຖະນາຖາວອນ
A3: ເຂດເສດຖະກິດພີເສດ ສະຫວັນ-ເຊໂນ | L3: >>>>>>>>000000<<<<<<<<<<
A4: ບໍລິສັດ ມີຢາໂມໂຕ ລາວ ຈຳກັດຜູ້ດຽວ
A5: ໂທລະສັບ :+8562023333500 | L5: ຕາຕະລາງຄິດໄລ່ເງິນ ໂອທີ ພະນັກງານ
L6: ປະຈຳວັນ ເດືອນ 06/2026
A7: ລ/ດ No. | B7: ລະຫັດພງ Emplyee ID | C7: ຊື່ ແລະ ນາສະກຸນ Name and Surname | D7: Telephone | E7: ຕຳແໜ່ງ Position | F7: ສັນຊາດ | G7: Days | H7: ເງິນເດືອນພື້ນຖານ Basic Salary | I7: ຄິດເປັນເງິນຕໍ່ 1ຊົວໂມງ | J7: ວັນຈັນ-ສຸກ 1.5 | K7: ຈຳນວນ ຊົວໂມງ | L7: ລວມເງິນ | M7: ວັນເສົາ 2 | N7: ຈຳນວນ ຊົວໂມງ | O7: ລວມເງິນ | P7: ວັນອາທີດ 2.5 | Q7: ຈຳນວນຊົວໂມງ | R7: ລວມເງິນ | S7: ລວມເງິນທັງໜົດ | T7: ອາກອນ 5% | U7: ລວມຈຳນວນເງິນ | V7: ເຊັນຮັບເງິນ
A8: 1 | B8: {=_xlfn._xlws.FILTER(TAX!$B$7:$H$98,TAX!H7:H98,TAX!$F$7:$F$98)} -> MYL000001 | C8: MR PHICHAI EIAMWATTANASILP | D8: 66617893562 | E8: Director | F8: ຕ່າງປະເທດ | G8: 26 | H8: 68067000 | I8: =H8/G8/8 -> 327245.19 | J8: =I8*1.5 -> 490867.79 | L8: =J8*K8 -> 0 | M8: =I8*2 -> 654490.38 | O8: =M8*N8 -> 0 | P8: =I8*2.5 -> 818112.98 | R8: =P8*Q8 -> 0 | S8: =L8+O8+R8 -> 0
A9: 2 | B9: MYL000005 | C9: MR WEERASIT LEEGCHOUR | D9: 2098388245 | E9: Deputy director 04 | F9: ຕ່າງປະເທດ | G9: 26 | H9: 13613400 | I9: =H9/G9/8 -> 65449.038 | J9: =I9*1.5 -> 98173.558 | L9: =J9*K9 -> 0 | M9: =I9*2 -> 130898.08 | O9: =M9*N9 -> 0 | P9: =I9*2.5 -> 163622.6 | R9: =P9*Q9 -> 0 | S9: =L9+O9+R9 -> 0
A10: 3 | B10: MYL000002 | C10: MRS Boualavanh BANPHACHA | D10: 2023333500 | E10: Deputy director 01 | F10: ພາຍໃນປະເທດ | G10: 26 | H10: 68067000 | I10: =H10/G10/8 -> 327245.19 | J10: =I10*1.5 -> 490867.79 | L10: =J10*K10 -> 0 | M10: =I10*2 -> 654490.38 | O10: =M10*N10 -> 0 | P10: =I10*2.5 -> 818112.98 | R10: =P10*Q10 -> 0 | S10: =L10+O10+R10 -> 0
A11: 4 | B11: MYL000003 | C11: MRS DATSANY BANPHAXA | D11: 2023333800 | E11: Deputy director 02 | F11: ພາຍໃນປະເທດ | G11: 26 | H11: 27226800 | I11: =H11/G11/8 -> 130898.08 | J11: =I11*1.5 -> 196347.12 | L11: =J11*K11 -> 0 | M11: =I11*2 -> 261796.15 | O11: =M11*N11 -> 0 | P11: =I11*2.5 -> 327245.19 | R11: =P11*Q11 -> 0 | S11: =L11+O11+R11 -> 0
A12: 5 | B12: MYL000004 | C12: MISS BOUAVONE VANGVONGXAI | D12: 2076198111 | E12: Deputy director 03 | F12: ພາຍໃນປະເທດ | G12: 26 | H12: 13000000 | I12: =H12/G12/8 -> 62500 | J12: =I12*1.5 -> 93750 | L12: =J12*K12 -> 0 | M12: =I12*2 -> 125000 | O12: =M12*N12 -> 0 | P12: =I12*2.5 -> 156250 | R12: =P12*Q12 -> 0 | S12: =L12+O12+R12 -> 0
A13: 6 | B13: MYL202210001 | C13: MR ANOUSACK THAMMAVONG | D13: 2077772708 | E13: Accounting | F13: ພາຍໃນປະເທດ | G13: 26 | H13: 10000000 | I13: =H13/G13/8 -> 48076.923 | J13: =I13*1.5 -> 72115.385 | L13: =J13*K13 -> 0 | M13: =I13*2 -> 96153.846 | O13: =M13*N13 -> 0 | P13: =I13*2.5 -> 120192.31 | R13: =P13*Q13 -> 0 | S13: =L13+O13+R13 -> 0
A14: 7 | B14: MYL202001001 | C14: MR SONESAVANH PHENGPHINIT | D14: 02092539860 | E14: Accounting | F14: ພາຍໃນປະເທດ | G14: 26 | H14: 6832000 | I14: =H14/G14/8 -> 32846.154 | J14: =I14*1.5 -> 49269.231 | L14: =J14*K14 -> 0 | M14: =I14*2 -> 65692.308 | O14: =M14*N14 -> 0 | P14: =I14*2.5 -> 82115.385 | R14: =P14*Q14 -> 0 | S14: =L14+O14+R14 -> 0
A15: 8 | B15: MYL202408005 | C15: MISS CHANSAMONE PHANTHALAVONG | D15: 2099701293 | E15: Planning | F15: ພາຍໃນປະເທດ | G15: 26 | H15: 6000000 | I15: =H15/G15/8 -> 28846.154 | J15: =I15*1.5 -> 43269.231 | L15: =J15*K15 -> 0 | M15: =I15*2 -> 57692.308 | O15: =M15*N15 -> 0 | P15: =I15*2.5 -> 72115.385 | R15: =P15*Q15 -> 0 | S15: =L15+O15+R15 -> 0
A16: 9 | B16: MYT202602136 | C16: MRS BOUANGUEN SOMCHANMAVONG | D16: 2056516668 | E16: Planning | F16: ພາຍໃນປະເທດ | G16: 26 | H16: 4500000 | I16: =H16/G16/8 -> 21634.615 | J16: =I16*1.5 -> 32451.923 | L16: =J16*K16 -> 0 | M16: =I16*2 -> 43269.231 | O16: =M16*N16 -> 0 | P16: =I16*2.5 -> 54086.538 | R16: =P16*Q16 -> 0 | S16: =L16+O16+R16 -> 0
A17: 10 | B17: MYL202606153 | C17: MR SEUAPA XAIYAVONG | D17: 2078150776 | E17: Planning | F17: ພາຍໃນປະເທດ | G17: 26 | H17: 3500000 | I17: =H17/G17/8 -> 16826.923 | J17: =I17*1.5 -> 25240.385 | L17: =J17*K17 -> 0 | M17: =I17*2 -> 33653.846 | O17: =M17*N17 -> 0 | P17: =I17*2.5 -> 42067.308 | R17: =P17*Q17 -> 0 | S17: =L17+O17+R17 -> 0
A18: 11 | B18: MYL202604144 | C18: MISS PHOSEE KIANGLANOUSIN | D18: 2076861520 | E18: OFFICE | F18: ພາຍໃນປະເທດ | G18: 26 | H18: 3500000 | I18: =H18/G18/8 -> 16826.923 | J18: =I18*1.5 -> 25240.385 | L18: =J18*K18 -> 0 | M18: =I18*2 -> 33653.846 | O18: =M18*N18 -> 0 | P18: =I18*2.5 -> 42067.308 | R18: =P18*Q18 -> 0 | S18: =L18+O18+R18 -> 0
A19: 12 | B19: MYL201908010 | C19: MR SAYSAMPHAN MANEEBOTH | D19: 2097545680 | E19: Logistic Staff | F19: ພາຍໃນປະເທດ | G19: 26 | H19: 5000000 | I19: =H19/G19/8 -> 24038.462 | J19: =I19*1.5 -> 36057.692 | L19: =J19*K19 -> 0 | M19: =I19*2 -> 48076.923 | O19: =M19*N19 -> 0 | P19: =I19*2.5 -> 60096.154 | R19: =P19*Q19 -> 0 | S19: =L19+O19+R19 -> 0
A20: 13 | B20: MYL202001036 | C20: MISS JINDA BANPHACHA | D20: 2092416077 | E20: Audit | F20: ພາຍໃນປະເທດ | G20: 26 | H20: 10550385 | I20: =H20/G20/8 -> 50723.005 | J20: =I20*1.5 -> 76084.507 | L20: =J20*K20 -> 0 | M20: =I20*2 -> 101446.01 | O20: =M20*N20 -> 0 | P20: =I20*2.5 -> 126807.51 | R20: =P20*Q20 -> 0 | S20: =L20+O20+R20 -> 0
A21: 14 | B21: MYL201908016 | C21: MR AMMALIN | D21: 2023332299 | E21: Production manager 02 | F21: ພາຍໃນປະເທດ | G21: 26 | H21: 5000000 | I21: =H21/G21/8 -> 24038.462 | J21: =I21*1.5 -> 36057.692 | L21: =J21*K21 -> 0 | M21: =I21*2 -> 48076.923 | O21: =M21*N21 -> 0 | P21: =I21*2.5 -> 60096.154 | R21: =P21*Q21 -> 0 | S21: =L21+O21+R21 -> 0
A22: 15 | B22: MYL202001049 | C22: MR BOUNPON | D22: 2078916853 | E22: Production manager 02 | F22: ພາຍໃນປະເທດ | G22: 26 | H22: 4000000 | I22: =H22/G22/8 -> 19230.769 | J22: =I22*1.5 -> 28846.154 | L22: =J22*K22 -> 0 | M22: =I22*2 -> 38461.538 | O22: =M22*N22 -> 0 | P22: =I22*2.5 -> 48076.923 | R22: =P22*Q22 -> 0 | S22: =L22+O22+R22 -> 0
A23: 16 | B23: MYL000009 | C23: MR SONE | D23: 0 | E23: Security Staff | F23: ພາຍໃນປະເທດ | G23: 26 | H23: 10550385 | I23: =H23/G23/8 -> 50723.005 | J23: =I23*1.5 -> 76084.507 | L23: =J23*K23 -> 0 | M23: =I23*2 -> 101446.01 | O23: =M23*N23 -> 0 | P23: =I23*2.5 -> 126807.51 | R23: =P23*Q23 -> 0 | S23: =L23+O23+R23 -> 0
A24: 17 | B24: MYL202401027 | C24: MRS NIK CHANTHANET | D24: 2056339678 | E24: Maid Staff | F24: ພາຍໃນປະເທດ | G24: 26 | H24: 2702000 | I24: =H24/G24/8 -> 12990.385 | J24: =I24*1.5 -> 19485.577 | L24: =J24*K24 -> 0 | M24: =I24*2 -> 25980.769 | O24: =M24*N24 -> 0 | P24: =I24*2.5 -> 32475.962 | R24: =P24*Q24 -> 0 | S24: =L24+O24+R24 -> 0
A25: 18 | B25: MYL201908028 | C25: MR TERY KHAMKOUNA | D25: 02059103026 | E25: Engineering | F25: ພາຍໃນປະເທດ | G25: 26 | H25: 5000000 | I25: =H25/G25/8 -> 24038.462 | J25: =I25*1.5 -> 36057.692 | L25: =J25*K25 -> 0 | M25: =I25*2 -> 48076.923 | O25: =M25*N25 -> 0 | P25: =I25*2.5 -> 60096.154 | R25: =P25*Q25 -> 0 | S25: =L25+O25+R25 -> 0
A26: 19 | B26: MYL202507076 | C26: MR XAYSONGKHAM SOMSANITH | D26: 2056211706 | E26: Engineering | F26: ພາຍໃນປະເທດ | G26: 26 | H26: 4500000 | I26: =H26/G26/8 -> 21634.615 | J26: =I26*1.5 -> 32451.923 | L26: =J26*K26 -> 0 | M26: =I26*2 -> 43269.231 | O26: =M26*N26 -> 0 | P26: =I26*2.5 -> 54086.538 | R26: =P26*Q26 -> 0 | S26: =L26+O26+R26 -> 0
A27: 20 | B27: MYL201908026 | C27: MR SONGKAN PHACHANSITTHI | D27: 2054612045 | E27: QC Manager 02 | F27: ພາຍໃນປະເທດ | G27: 26 | H27: 4000000 | I27: =H27/G27/8 -> 19230.769 | J27: =I27*1.5 -> 28846.154 | L27: =J27*K27 -> 0 | M27: =I27*2 -> 38461.538 | O27: =M27*N27 -> 0 | P27: =I27*2.5 -> 48076.923 | R27: =P27*Q27 -> 0 | S27: =L27+O27+R27 -> 0
A28: 21 | B28: MYL202504064 | C28: MISS NALIN SYHALATH | D28: 2098953256 | E28: QC PTS | F28: ພາຍໃນປະເທດ | G28: 26 | H28: 2600000 | I28: =H28/G28/8 -> 12500 | J28: =I28*1.5 -> 18750 | L28: =J28*K28 -> 0 | M28: =I28*2 -> 25000 | O28: =M28*N28 -> 0 | P28: =I28*2.5 -> 31250 | R28: =P28*Q28 -> 0 | S28: =L28+O28+R28 -> 0
A29: 22 | B29: MYL202606160 | C29: MISS LAMPHAI THUMMAVONGE | D29: 2091381527 | E29: QC SAS | F29: ພາຍໃນປະເທດ | G29: 26 | H29: 2500000 | I29: =H29/G29/8 -> 12019.231 | J29: =I29*1.5 -> 18028.846 | L29: =J29*K29 -> 0 | M29: =I29*2 -> 24038.462 | O29: =M29*N29 -> 0 | P29: =I29*2.5 -> 30048.077 | R29: =P29*Q29 -> 0 | S29: =L29+O29+R29 -> 0
A30: 23 | B30: MYL202301037 | C30: MRS PHOULATSAMY SETTHATHILATH | D30: 2077074510 | E30: STORE PTS | F30: ພາຍໃນປະເທດ | G30: 26 | H30: 3300000 | I30: =H30/G30/8 -> 15865.385 | J30: =I30*1.5 -> 23798.077 | L30: =J30*K30 -> 0 | M30: =I30*2 -> 31730.769 | O30: =M30*N30 -> 0 | P30: =I30*2.5 -> 39663.462 | R30: =P30*Q30 -> 0 | S30: =L30+O30+R30 -> 0
A31: 24 | B31: MYT202602133 | C31: MR BOUNTHAVY KOMKAIYASONE | D31: 2097221714 | E31: STORE PTS | F31: ພາຍໃນປະເທດ | G31: 26 | H31: 2600000 | I31: =H31/G31/8 -> 12500 | J31: =I31*1.5 -> 18750 | L31: =J31*K31 -> 0 | M31: =I31*2 -> 25000 | O31: =M31*N31 -> 0 | P31: =I31*2.5 -> 31250 | R31: =P31*Q31 -> 0 | S31: =L31+O31+R31 -> 0
A32: 25 | B32: MYL202404006 | C32: MR SENGMANY PHATTHANA | D32: 2059597282 | E32: STORE OTS | F32: ພາຍໃນປະເທດ | G32: 26 | H32: 3300000 | I32: =H32/G32/8 -> 15865.385 | J32: =I32*1.5 -> 23798.077 | K32: 1 | L32: =J32*K32 -> 23798.077 | M32: =I32*2 -> 31730.769 | O32: =M32*N32 -> 0 | P32: =I32*2.5 -> 39663.462 | R32: =P32*Q32 -> 0 | S32: =L32+O32+R32 -> 23798.077
A33: 26 | B33: MYL202601128 | C33: MR KHAMPHASITH XAYYAJACK | D33: 2077412771 | E33: STORE OTS | F33: ພາຍໃນປະເທດ | G33: 26 | H33: 2600000 | I33: =H33/G33/8 -> 12500 | J33: =I33*1.5 -> 18750 | K33: 2 | L33: =J33*K33 -> 37500 | M33: =I33*2 -> 25000 | O33: =M33*N33 -> 0 | P33: =I33*2.5 -> 31250 | R33: =P33*Q33 -> 0 | S33: =L33+O33+R33 -> 37500
A34: 27 | B34: MYL202606162 | C34: MISS KHONESAVANH CHANTHALAY | D34: 2096532048 | E34: STORE OTS | F34: ພາຍໃນປະເທດ | G34: 26 | H34: 2500000 | I34: =H34/G34/8 -> 12019.231 | J34: =I34*1.5 -> 18028.846 | L34: =J34*K34 -> 0 | M34: =I34*2 -> 24038.462 | O34: =M34*N34 -> 0 | P34: =I34*2.5 -> 30048.077 | R34: =P34*Q34 -> 0 | S34: =L34+O34+R34 -> 0
A35: 28 | B35: MYL202001035 | C35: MRS TOUKTA PONGSIMMALY | D35: 2057706864 | E35: STORE SAS | F35: ພາຍໃນປະເທດ | G35: 26 | H35: 3300000 | I35: =H35/G35/8 -> 15865.385 | J35: =I35*1.5 -> 23798.077 | K35: 1 | L35: =J35*K35 -> 23798.077 | M35: =I35*2 -> 31730.769 | O35: =M35*N35 -> 0 | P35: =I35*2.5 -> 39663.462 | R35: =P35*Q35 -> 0 | S35: =L35+O35+R35 -> 23798.077
A36: 29 | B36: MYL202605151 | C36: MR SOULIYA | D36: 2099427578 | E36: STORE SAS | F36: ພາຍໃນປະເທດ | G36: 26 | H36: 2600000 | I36: =H36/G36/8 -> 12500 | J36: =I36*1.5 -> 18750 | L36: =J36*K36 -> 0 | M36: =I36*2 -> 25000 | O36: =M36*N36 -> 0 | P36: =I36*2.5 -> 31250 | R36: =P36*Q36 -> 0 | S36: =L36+O36+R36 -> 0
A37: 30 | B37: MYL202201050 | C37: MR TOUTONNAM KHOUNSAVANH | D37: 2093949318 | E37: Welding PTS | F37: ພາຍໃນປະເທດ | G37: 26 | H37: 3300000 | I37: =H37/G37/8 -> 15865.385 | J37: =I37*1.5 -> 23798.077 | L37: =J37*K37 -> 0 | M37: =I37*2 -> 31730.769 | O37: =M37*N37 -> 0 | P37: =I37*2.5 -> 39663.462 | R37: =P37*Q37 -> 0 | S37: =L37+O37+R37 -> 0
A38: 31 | B38: MYL202502061 | C38: MR KHONESAVANH SYTHAVONG | D38: 2096870409 | E38: Welding PTS | F38: ພາຍໃນປະເທດ | G38: 26 | H38: 2600000 | I38: =H38/G38/8 -> 12500 | J38: =I38*1.5 -> 18750 | L38: =J38*K38 -> 0 | M38: =I38*2 -> 25000 | O38: =M38*N38 -> 0 | P38: =I38*2.5 -> 31250 | R38: =P38*Q38 -> 0 | S38: =L38+O38+R38 -> 0
A39: 32 | B39: MYL202504072 | C39: MR BACKHAM XAISONGKHAM | D39: 2093768539 | E39: Welding PTS | F39: ພາຍໃນປະເທດ | G39: 26 | H39: 2600000 | I39: =H39/G39/8 -> 12500 | J39: =I39*1.5 -> 18750 | L39: =J39*K39 -> 0 | M39: =I39*2 -> 25000 | O39: =M39*N39 -> 0 | P39: =I39*2.5 -> 31250 | R39: =P39*Q39 -> 0 | S39: =L39+O39+R39 -> 0
A40: 33 | B40: MYL202509108 | C40: MR SEEVA PONGSIMMALY | D40: 2056238018 | E40: Welding PTS | F40: ພາຍໃນປະເທດ | G40: 26 | H40: 2600000 | I40: =H40/G40/8 -> 12500 | J40: =I40*1.5 -> 18750 | L40: =J40*K40 -> 0 | M40: =I40*2 -> 25000 | O40: =M40*N40 -> 0 | P40: =I40*2.5 -> 31250 | R40: =P40*Q40 -> 0 | S40: =L40+O40+R40 -> 0
...

Sheet เงินกะ
A5: ຕາຕະລາງຄິດໄລ່ເງີນກະກາງຄືນ ປະຈຳເດືອນ 06/2026
A6: ລ/ດ No. | B6: ລະຫັດພງ Emplyee ID | C6: ຊື່ ແລະ ນາສະກຸນ Name and Surname | D6: Telephone | E6: ຕຳແໜ່ງ Position | F6: ສັນຊາດ | G6: Days | H6: ເງິນເດືອນພື້ນຖານ Basic Salary | I6: Days | J6: 0.15 | K6: ລວມ | L6: ຈຳນວນ | M6: ລວມ
I7: =SUBTOTAL(109,I8:I100) -> 2046357.8 | J7: =SUBTOTAL(109,J8:J100) -> 306953.68 | K7: =SUBTOTAL(109,K8:K100) -> 2353311.5 | L7: =SUBTOTAL(109,L8:L100) -> 233.5 | M7: =SUBTOTAL(109,M8:M100) -> 3407674.8
A8: {=_xlfn.SEQUENCE(COUNTA(B8:B173))} -> 1 | B8: {=_xlfn._xlws.FILTER(TAX!$B$7:$H$98,TAX!H7:H98,TAX!$F$7:$F$98)} -> MYL000001 | C8: MR PHICHAI EIAMWATTANASILP | D8: 66617893562 | E8: Director | F8: ຕ່າງປະເທດ | G8: 26 | H8: 68067000 | I8: =H8/G8/8 -> 327245.19 | J8: =I8*$J$6 -> 49086.779 | K8: =I8+J8 -> 376331.97 | M8: =K8*L8 -> 0
B9: MYL000005 | C9: MR WEERASIT LEEGCHOUR | D9: 2098388245 | E9: Deputy director 04 | F9: ຕ່າງປະເທດ | G9: 26 | H9: 13613400 | I9: =H9/G9/8 -> 65449.038 | J9: =I9*$J$6 -> 9817.3558 | K9: =I9+J9 -> 75266.394 | M9: =K9*L9 -> 0
B10: MYL000002 | C10: MRS Boualavanh BANPHACHA | D10: 2023333500 | E10: Deputy director 01 | F10: ພາຍໃນປະເທດ | G10: 26 | H10: 68067000 | I10: =H10/G10/8 -> 327245.19 | J10: =I10*$J$6 -> 49086.779 | K10: =I10+J10 -> 376331.97 | M10: =K10*L10 -> 0
B11: MYL000003 | C11: MRS DATSANY BANPHAXA | D11: 2023333800 | E11: Deputy director 02 | F11: ພາຍໃນປະເທດ | G11: 26 | H11: 27226800 | I11: =H11/G11/8 -> 130898.08 | J11: =I11*$J$6 -> 19634.712 | K11: =I11+J11 -> 150532.79 | M11: =K11*L11 -> 0
B12: MYL000004 | C12: MISS BOUAVONE VANGVONGXAI | D12: 2076198111 | E12: Deputy director 03 | F12: ພາຍໃນປະເທດ | G12: 26 | H12: 13000000 | I12: =H12/G12/8 -> 62500 | J12: =I12*$J$6 -> 9375 | K12: =I12+J12 -> 71875 | M12: =K12*L12 -> 0
B13: MYL202210001 | C13: MR ANOUSACK THAMMAVONG | D13: 2077772708 | E13: Accounting | F13: ພາຍໃນປະເທດ | G13: 26 | H13: 10000000 | I13: =H13/G13/8 -> 48076.923 | J13: =I13*$J$6 -> 7211.5385 | K13: =I13+J13 -> 55288.462 | M13: =K13*L13 -> 0
B14: MYL202001001 | C14: MR SONESAVANH PHENGPHINIT | D14: 02092539860 | E14: Accounting | F14: ພາຍໃນປະເທດ | G14: 26 | H14: 6832000 | I14: =H14/G14/8 -> 32846.154 | J14: =I14*$J$6 -> 4926.9231 | K14: =I14+J14 -> 37773.077 | M14: =K14*L14 -> 0
B15: MYL202408005 | C15: MISS CHANSAMONE PHANTHALAVONG | D15: 2099701293 | E15: Planning | F15: ພາຍໃນປະເທດ | G15: 26 | H15: 6000000 | I15: =H15/G15/8 -> 28846.154 | J15: =I15*$J$6 -> 4326.9231 | K15: =I15+J15 -> 33173.077 | M15: =K15*L15 -> 0
B16: MYT202602136 | C16: MRS BOUANGUEN SOMCHANMAVONG | D16: 2056516668 | E16: Planning | F16: ພາຍໃນປະເທດ | G16: 26 | H16: 4500000 | I16: =H16/G16/8 -> 21634.615 | J16: =I16*$J$6 -> 3245.1923 | K16: =I16+J16 -> 24879.808 | M16: =K16*L16 -> 0
B17: MYL202606153 | C17: MR SEUAPA XAIYAVONG | D17: 2078150776 | E17: Planning | F17: ພາຍໃນປະເທດ | G17: 26 | H17: 3500000 | I17: =H17/G17/8 -> 16826.923 | J17: =I17*$J$6 -> 2524.0385 | K17: =I17+J17 -> 19350.962 | M17: =K17*L17 -> 0
B18: MYL202604144 | C18: MISS PHOSEE KIANGLANOUSIN | D18: 2076861520 | E18: OFFICE | F18: ພາຍໃນປະເທດ | G18: 26 | H18: 3500000 | I18: =H18/G18/8 -> 16826.923 | J18: =I18*$J$6 -> 2524.0385 | K18: =I18+J18 -> 19350.962 | M18: =K18*L18 -> 0
B19: MYL201908010 | C19: MR SAYSAMPHAN MANEEBOTH | D19: 2097545680 | E19: Logistic Staff | F19: ພາຍໃນປະເທດ | G19: 26 | H19: 5000000 | I19: =H19/G19/8 -> 24038.462 | J19: =I19*$J$6 -> 3605.7692 | K19: =I19+J19 -> 27644.231 | M19: =K19*L19 -> 0
B20: MYL202001036 | C20: MISS JINDA BANPHACHA | D20: 2092416077 | E20: Audit | F20: ພາຍໃນປະເທດ | G20: 26 | H20: 10550385 | I20: =H20/G20/8 -> 50723.005 | J20: =I20*$J$6 -> 7608.4507 | K20: =I20+J20 -> 58331.456 | M20: =K20*L20 -> 0
B21: MYL201908016 | C21: MR AMMALIN | D21: 2023332299 | E21: Production manager 02 | F21: ພາຍໃນປະເທດ | G21: 26 | H21: 5000000 | I21: =H21/G21/8 -> 24038.462 | J21: =I21*$J$6 -> 3605.7692 | K21: =I21+J21 -> 27644.231 | M21: =K21*L21 -> 0
B22: MYL202001049 | C22: MR BOUNPON | D22: 2078916853 | E22: Production manager 02 | F22: ພາຍໃນປະເທດ | G22: 26 | H22: 4000000 | I22: =H22/G22/8 -> 19230.769 | J22: =I22*$J$6 -> 2884.6154 | K22: =I22+J22 -> 22115.385 | M22: =K22*L22 -> 0
B23: MYL000009 | C23: MR SONE | D23: 0 | E23: Security Staff | F23: ພາຍໃນປະເທດ | G23: 26 | H23: 10550385 | I23: =H23/G23/8 -> 50723.005 | J23: =I23*$J$6 -> 7608.4507 | K23: =I23+J23 -> 58331.456 | M23: =K23*L23 -> 0
B24: MYL202401027 | C24: MRS NIK CHANTHANET | D24: 2056339678 | E24: Maid Staff | F24: ພາຍໃນປະເທດ | G24: 26 | H24: 2702000 | I24: =H24/G24/8 -> 12990.385 | J24: =I24*$J$6 -> 1948.5577 | K24: =I24+J24 -> 14938.942 | M24: =K24*L24 -> 0
B25: MYL201908028 | C25: MR TERY KHAMKOUNA | D25: 02059103026 | E25: Engineering | F25: ພາຍໃນປະເທດ | G25: 26 | H25: 5000000 | I25: =H25/G25/8 -> 24038.462 | J25: =I25*$J$6 -> 3605.7692 | K25: =I25+J25 -> 27644.231 | M25: =K25*L25 -> 0
B26: MYL202507076 | C26: MR XAYSONGKHAM SOMSANITH | D26: 2056211706 | E26: Engineering | F26: ພາຍໃນປະເທດ | G26: 26 | H26: 4500000 | I26: =H26/G26/8 -> 21634.615 | J26: =I26*$J$6 -> 3245.1923 | K26: =I26+J26 -> 24879.808 | M26: =K26*L26 -> 0
B27: MYL201908026 | C27: MR SONGKAN PHACHANSITTHI | D27: 2054612045 | E27: QC Manager 02 | F27: ພາຍໃນປະເທດ | G27: 26 | H27: 4000000 | I27: =H27/G27/8 -> 19230.769 | J27: =I27*$J$6 -> 2884.6154 | K27: =I27+J27 -> 22115.385 | M27: =K27*L27 -> 0
B28: MYL202504064 | C28: MISS NALIN SYHALATH | D28: 2098953256 | E28: QC PTS | F28: ພາຍໃນປະເທດ | G28: 26 | H28: 2600000 | I28: =H28/G28/8 -> 12500 | J28: =I28*$J$6 -> 1875 | K28: =I28+J28 -> 14375 | M28: =K28*L28 -> 0
B29: MYL202606160 | C29: MISS LAMPHAI THUMMAVONGE | D29: 2091381527 | E29: QC SAS | F29: ພາຍໃນປະເທດ | G29: 26 | H29: 2500000 | I29: =H29/G29/8 -> 12019.231 | J29: =I29*$J$6 -> 1802.8846 | K29: =I29+J29 -> 13822.115 | M29: =K29*L29 -> 0
B30: MYL202301037 | C30: MRS PHOULATSAMY SETTHATHILATH | D30: 2077074510 | E30: STORE PTS | F30: ພາຍໃນປະເທດ | G30: 26 | H30: 3300000 | I30: =H30/G30/8 -> 15865.385 | J30: =I30*$J$6 -> 2379.8077 | K30: =I30+J30 -> 18245.192 | M30: =K30*L30 -> 0
B31: MYT202602133 | C31: MR BOUNTHAVY KOMKAIYASONE | D31: 2097221714 | E31: STORE PTS | F31: ພາຍໃນປະເທດ | G31: 26 | H31: 2600000 | I31: =H31/G31/8 -> 12500 | J31: =I31*$J$6 -> 1875 | K31: =I31+J31 -> 14375 | M31: =K31*L31 -> 0
B32: MYL202404006 | C32: MR SENGMANY PHATTHANA | D32: 2059597282 | E32: STORE OTS | F32: ພາຍໃນປະເທດ | G32: 26 | H32: 3300000 | I32: =H32/G32/8 -> 15865.385 | J32: =I32*$J$6 -> 2379.8077 | K32: =I32+J32 -> 18245.192 | L32: 2 | M32: =K32*L32 -> 36490.385
B33: MYL202601128 | C33: MR KHAMPHASITH XAYYAJACK | D33: 2077412771 | E33: STORE OTS | F33: ພາຍໃນປະເທດ | G33: 26 | H33: 2600000 | I33: =H33/G33/8 -> 12500 | J33: =I33*$J$6 -> 1875 | K33: =I33+J33 -> 14375 | M33: =K33*L33 -> 0
B34: MYL202606162 | C34: MISS KHONESAVANH CHANTHALAY | D34: 2096532048 | E34: STORE OTS | F34: ພາຍໃນປະເທດ | G34: 26 | H34: 2500000 | I34: =H34/G34/8 -> 12019.231 | J34: =I34*$J$6 -> 1802.8846 | K34: =I34+J34 -> 13822.115 | M34: =K34*L34 -> 0
B35: MYL202001035 | C35: MRS TOUKTA PONGSIMMALY | D35: 2057706864 | E35: STORE SAS | F35: ພາຍໃນປະເທດ | G35: 26 | H35: 3300000 | I35: =H35/G35/8 -> 15865.385 | J35: =I35*$J$6 -> 2379.8077 | K35: =I35+J35 -> 18245.192 | M35: =K35*L35 -> 0
B36: MYL202605151 | C36: MR SOULIYA | D36: 2099427578 | E36: STORE SAS | F36: ພາຍໃນປະເທດ | G36: 26 | H36: 2600000 | I36: =H36/G36/8 -> 12500 | J36: =I36*$J$6 -> 1875 | K36: =I36+J36 -> 14375 | M36: =K36*L36 -> 0
